{'id': 6278927189, 'is_bot': True, 'first_name': 'Fast Food DEMO', 'username': 'fastfooddemo1bot', 'last_name': None, 'language_code': None, 'can_join_groups': True, 'can_read_all_group_messages': False, 'supports_inline_queries': False, 'is_premium': None, 'added_to_attachment_menu': None}
/home/venv/lib/python3.10/site-packages/django/db/models/fields/__init__.py:1504: RuntimeWarning: DateTimeField BotUser.created received a naive datetime (2023-06-15 00:00:00) while time zone support is active.
  warnings.warn(
[<telebot.types.InlineKeyboardButton object at 0x7f82e4099060>, <telebot.types.InlineKeyboardButton object at 0x7f82e15c1ab0>, <telebot.types.InlineKeyboardButton object at 0x7f82e15c1bd0>]
123 {'id': '4081716317277446780', 'from_user': {'id': 950348637, 'is_bot': False, 'first_name': 'Azim', 'username': 'AbdukhalilovAzim', 'last_name': 'Abdukhalilov', 'language_code': 'en', 'can_join_groups': None, 'can_read_all_group_messages': None, 'supports_inline_queries': None, 'is_premium': None, 'added_to_attachment_menu': None}, 'message': {'content_type': 'photo', 'id': 31, 'message_id': 31, 'from_user': <telebot.types.User object at 0x7f82e404bd00>, 'date': 1686836306, 'chat': <telebot.types.Chat object at 0x7f82e404bf70>, 'sender_chat': None, 'forward_from': None, 'forward_from_chat': None, 'forward_from_message_id': None, 'forward_signature': None, 'forward_sender_name': None, 'forward_date': None, 'is_automatic_forward': None, 'reply_to_message': None, 'via_bot': None, 'edit_date': None, 'has_protected_content': None, 'media_group_id': None, 'author_signature': None, 'text': None, 'entities': None, 'caption_entities': [<telebot.types.MessageEntity object at 0x7f82e404b880>, <telebot.types.MessageEntity object at 0x7f82e409a4d0>, <telebot.types.MessageEntity object at 0x7f82e4099690>, <telebot.types.MessageEntity object at 0x7f82e4099030>, <telebot.types.MessageEntity object at 0x7f82e409a0b0>, <telebot.types.MessageEntity object at 0x7f82e409b190>], 'audio': None, 'document': None, 'photo': [<telebot.types.PhotoSize object at 0x7f82e4098bb0>, <telebot.types.PhotoSize object at 0x7f82e4098c10>, <telebot.types.PhotoSize object at 0x7f82e409baf0>], 'sticker': None, 'video': None, 'video_note': None, 'voice': None, 'caption': "üîñ Nomi: Pitsa Pepperoni\n\nüåÆ Kategoriya: üçï Popironi\n\nkichik pitsa - 110000 So`m\n\no`rtacha pitsa - 120000 So`m\n\nKatta pitsa - 130000 So`m\n\n \n\nüìú Uyda klassik italyan pitssasini pishirish ko'p vaqt talab etadi, ammo bu qiyin emas. Garchi ko'p odamlar boshqacha fikrda bo'lsa ham. Ammo uyda tayyorlangan pepperoni pitssasining ta'mi ancha yaxshi. Eng qiyin narsa birinchi marta boshlashdir. Va keyin ozgina vaqt ketadi, xamir muzlatgichda mukammal saqlanadi.", 'contact': None, 'location': None, 'venue': None, 'animation': None, 'dice': None, 'new_chat_member': None, 'new_chat_members': None, 'left_chat_member': None, 'new_chat_title': None, 'new_chat_photo': None, 'delete_chat_photo': None, 'group_chat_created': None, 'supergroup_chat_created': None, 'channel_chat_created': None, 'migrate_to_chat_id': None, 'migrate_from_chat_id': None, 'pinned_message': None, 'invoice': None, 'successful_payment': None, 'connected_website': None, 'reply_markup': <telebot.types.InlineKeyboardMarkup object at 0x7f82e4049570>, 'message_thread_id': None, 'is_topic_message': None, 'forum_topic_created': None, 'forum_topic_closed': None, 'forum_topic_reopened': None, 'has_media_spoiler': None, 'forum_topic_edited': None, 'general_forum_topic_hidden': None, 'general_forum_topic_unhidden': None, 'write_access_allowed': None, 'user_shared': None, 'chat_shared': None, 'json': {'message_id': 31, 'from': {'id': 6278927189, 'is_bot': True, 'first_name': 'Fast Food DEMO', 'username': 'fastfooddemo1bot'}, 'chat': {'id': 950348637, 'first_name': 'Azim', 'last_name': 'Abdukhalilov', 'username': 'AbdukhalilovAzim', 'type': 'private'}, 'date': 1686836306, 'photo': [{'file_id': 'AgACAgIAAxkDAAMfZIsUUqEp7x_TSgaDn_l9mAlHaRkAAhPKMRuBXlhIX8Z9wkiUWF4BAAMCAANzAAMvBA', 'file_unique_id': 'AQADE8oxG4FeWEh4', 'file_size': 1921, 'width': 60, 'height': 90}, {'file_id': 'AgACAgIAAxkDAAMfZIsUUqEp7x_TSgaDn_l9mAlHaRkAAhPKMRuBXlhIX8Z9wkiUWF4BAAMCAANtAAMvBA', 'file_unique_id': 'AQADE8oxG4FeWEhy', 'file_size': 33389, 'width': 213, 'height': 320}, {'file_id': 'AgACAgIAAxkDAAMfZIsUUqEp7x_TSgaDn_l9mAlHaRkAAhPKMRuBXlhIX8Z9wkiUWF4BAAMCAAN4AAMvBA', 'file_unique_id': 'AQADE8oxG4FeWEh9', 'file_size': 138148, 'width': 525, 'height': 788}], 'caption': "üîñ Nomi: Pitsa Pepperoni\n\nüåÆ Kategoriya: üçï Popironi\n\nkichik pitsa - 110000 So`m\n\no`rtacha pitsa - 120000 So`m\n\nKatta pitsa - 130000 So`m\n\n \n\nüìú Uyda klassik italyan pitssasini pishirish ko'p vaqt talab etadi, ammo bu qiyin emas. Garchi ko'p odamlar boshqacha fikrda bo'lsa ham. Ammo uyda tayyorlangan pepperoni pitssasining ta'mi ancha yaxshi. Eng qiyin narsa birinchi marta boshlashdir. Va keyin ozgina vaqt ketadi, xamir muzlatgichda mukammal saqlanadi.", 'caption_entities': [{'offset': 0, 'length': 8, 'type': 'bold'}, {'offset': 9, 'length': 15, 'type': 'italic'}, {'offset': 26, 'length': 14, 'type': 'bold'}, {'offset': 41, 'length': 11, 'type': 'italic'}, {'offset': 54, 'length': 86, 'type': 'bold'}, {'offset': 142, 'length': 314, 'type': 'bold'}], 'reply_markup': {'inline_keyboard': [[{'text': '‚¨ÖÔ∏è', 'callback_data': 'type:PurchasePage|page:0'}, {'text': '1', 'callback_data': 'type:Nothing'}, {'text': '‚û°Ô∏è', 'callback_data': 'type:PurchasePage|page:0'}], [{'text': '‚ûñ', 'callback_data': 'type:PurchaseCount|page:0|count:0'}, {'text': '1', 'callback_data': 'type:Nothing'}, {'text': '‚ûï', 'callback_data': 'type:PurchaseCount|page:0|count:2'}], [{'text': '‚ùå', 'callback_data': 'type:PurchaseRemove|page:0'}], [{'text': "üí∞ Sotib olish (110000 so'm)", 'callback_data': 'type:PurchaseBuy|page:0'}], [{'text': "üí∞ Sotib olish hammasini (110000 so'm)", 'callback_data': 'type:PurchasesBuy'}], [{'text': 'üîô Orqaga', 'callback_data': 'type:Back'}]]}}}, 'inline_message_id': None, 'chat_instance': '-3881008577599662282', 'data': 'type:PurchaseBuy|page:0', 'game_short_name': None, 'json': {'id': '4081716317277446780', 'from': {'id': 950348637, 'is_bot': False, 'first_name': 'Azim', 'last_name': 'Abdukhalilov', 'username': 'AbdukhalilovAzim', 'language_code': 'en'}, 'message': {'message_id': 31, 'from': {'id': 6278927189, 'is_bot': True, 'first_name': 'Fast Food DEMO', 'username': 'fastfooddemo1bot'}, 'chat': {'id': 950348637, 'first_name': 'Azim', 'last_name': 'Abdukhalilov', 'username': 'AbdukhalilovAzim', 'type': 'private'}, 'date': 1686836306, 'photo': [{'file_id': 'AgACAgIAAxkDAAMfZIsUUqEp7x_TSgaDn_l9mAlHaRkAAhPKMRuBXlhIX8Z9wkiUWF4BAAMCAANzAAMvBA', 'file_unique_id': 'AQADE8oxG4FeWEh4', 'file_size': 1921, 'width': 60, 'height': 90}, {'file_id': 'AgACAgIAAxkDAAMfZIsUUqEp7x_TSgaDn_l9mAlHaRkAAhPKMRuBXlhIX8Z9wkiUWF4BAAMCAANtAAMvBA', 'file_unique_id': 'AQADE8oxG4FeWEhy', 'file_size': 33389, 'width': 213, 'height': 320}, {'file_id': 'AgACAgIAAxkDAAMfZIsUUqEp7x_TSgaDn_l9mAlHaRkAAhPKMRuBXlhIX8Z9wkiUWF4BAAMCAAN4AAMvBA', 'file_unique_id': 'AQADE8oxG4FeWEh9', 'file_size': 138148, 'width': 525, 'height': 788}], 'caption': "üîñ Nomi: Pitsa Pepperoni\n\nüåÆ Kategoriya: üçï Popironi\n\nkichik pitsa - 110000 So`m\n\no`rtacha pitsa - 120000 So`m\n\nKatta pitsa - 130000 So`m\n\n \n\nüìú Uyda klassik italyan pitssasini pishirish ko'p vaqt talab etadi, ammo bu qiyin emas. Garchi ko'p odamlar boshqacha fikrda bo'lsa ham. Ammo uyda tayyorlangan pepperoni pitssasining ta'mi ancha yaxshi. Eng qiyin narsa birinchi marta boshlashdir. Va keyin ozgina vaqt ketadi, xamir muzlatgichda mukammal saqlanadi.", 'caption_entities': [{'offset': 0, 'length': 8, 'type': 'bold'}, {'offset': 9, 'length': 15, 'type': 'italic'}, {'offset': 26, 'length': 14, 'type': 'bold'}, {'offset': 41, 'length': 11, 'type': 'italic'}, {'offset': 54, 'length': 86, 'type': 'bold'}, {'offset': 142, 'length': 314, 'type': 'bold'}], 'reply_markup': {'inline_keyboard': [[{'text': '‚¨ÖÔ∏è', 'callback_data': 'type:PurchasePage|page:0'}, {'text': '1', 'callback_data': 'type:Nothing'}, {'text': '‚û°Ô∏è', 'callback_data': 'type:PurchasePage|page:0'}], [{'text': '‚ûñ', 'callback_data': 'type:PurchaseCount|page:0|count:0'}, {'text': '1', 'callback_data': 'type:Nothing'}, {'text': '‚ûï', 'callback_data': 'type:PurchaseCount|page:0|count:2'}], [{'text': '‚ùå', 'callback_data': 'type:PurchaseRemove|page:0'}], [{'text': "üí∞ Sotib olish (110000 so'm)", 'callback_data': 'type:PurchaseBuy|page:0'}], [{'text': "üí∞ Sotib olish hammasini (110000 so'm)", 'callback_data': 'type:PurchasesBuy'}], [{'text': 'üîô Orqaga', 'callback_data': 'type:Back'}]]}}, 'chat_instance': '-3881008577599662282', 'data': 'type:PurchaseBuy|page:0'}}
1
2023-06-15 18:38:34,205 (__init__.py:1083 MainThread) ERROR - TeleBot: "Threaded polling exception: A request to the Telegram API was unsuccessful. Error code: 400. Description: Bad Request: message to edit not found"
2023-06-15 18:38:34,206 (__init__.py:1085 MainThread) ERROR - TeleBot: "Exception traceback:
Traceback (most recent call last):
  File "/home/venv/lib/python3.10/site-packages/telebot/__init__.py", line 1074, in __threaded_polling
    self.worker_pool.raise_exceptions()
  File "/home/venv/lib/python3.10/site-packages/telebot/util.py", line 148, in raise_exceptions
    raise self.exception_info
  File "/home/venv/lib/python3.10/site-packages/telebot/util.py", line 91, in run
    task(*args, **kwargs)
  File "/home/venv/lib/python3.10/site-packages/telebot/__init__.py", line 6428, in _run_middlewares_and_handler
    result = handler['function'](message)
  File "/home/fast_food_bot/bot/main.py", line 147, in callback_query_handler
    shopcard.delivery_type_call_handler(bot, call)
  File "/home/fast_food_bot/bot/shopcard.py", line 354, in delivery_type_call_handler
    ordering_finish(bot, user, call.message, delivery_type)
  File "/home/fast_food_bot/bot/shopcard.py", line 473, in ordering_finish
    bot.edit_message_text(
  File "/home/venv/lib/python3.10/site-packages/telebot/__init__.py", line 3679, in edit_message_text
    result = apihelper.edit_message_text(self.token, text, chat_id, message_id, inline_message_id, parse_mode,
  File "/home/venv/lib/python3.10/site-packages/telebot/apihelper.py", line 1269, in edit_message_text
    return _make_request(token, method_url, params=payload, method='post')
  File "/home/venv/lib/python3.10/site-packages/telebot/apihelper.py", line 162, in _make_request
    json_result = _check_result(method_name, result)
  File "/home/venv/lib/python3.10/site-packages/telebot/apihelper.py", line 189, in _check_result
    raise ApiTelegramException(method_name, result, result_json)
telebot.apihelper.ApiTelegramException: A request to the Telegram API was unsuccessful. Error code: 400. Description: Bad Request: message to edit not found
"
/home/fast_food_bot/bot/orders.py:50: UnorderedObjectListWarning: Pagination may yield inconsistent results with an unordered object_list: <class 'backend.models.Order'> QuerySet.
  paginator = Paginator(orders, 1)
2023-06-17 06:10:25,934 (__init__.py:1083 MainThread) ERROR - TeleBot: "Threaded polling exception: A request to the Telegram API was unsuccessful. Error code: 429. Description: Too Many Requests: retry after 5"
2023-06-17 06:10:25,936 (__init__.py:1085 MainThread) ERROR - TeleBot: "Exception traceback:
Traceback (most recent call last):
  File "/home/venv/lib/python3.10/site-packages/telebot/__init__.py", line 1073, in __threaded_polling
    polling_thread.raise_exceptions()
  File "/home/venv/lib/python3.10/site-packages/telebot/util.py", line 109, in raise_exceptions
    raise self.exception_info
  File "/home/venv/lib/python3.10/site-packages/telebot/util.py", line 91, in run
    task(*args, **kwargs)
  File "/home/venv/lib/python3.10/site-packages/telebot/__init__.py", line 649, in __retrieve_updates
    updates = self.get_updates(offset=(self.last_update_id + 1),
  File "/home/venv/lib/python3.10/site-packages/telebot/__init__.py", line 623, in get_updates
    json_updates = apihelper.get_updates(self.token, offset, limit, timeout, allowed_updates, long_polling_timeout)
  File "/home/venv/lib/python3.10/site-packages/telebot/apihelper.py", line 321, in get_updates
    return _make_request(token, method_url, params=payload)
  File "/home/venv/lib/python3.10/site-packages/telebot/apihelper.py", line 162, in _make_request
    json_result = _check_result(method_name, result)
  File "/home/venv/lib/python3.10/site-packages/telebot/apihelper.py", line 189, in _check_result
    raise ApiTelegramException(method_name, result, result_json)
telebot.apihelper.ApiTelegramException: A request to the Telegram API was unsuccessful. Error code: 429. Description: Too Many Requests: retry after 5
"
2023-06-17 06:10:26,235 (__init__.py:1083 MainThread) ERROR - TeleBot: "Threaded polling exception: A request to the Telegram API was unsuccessful. Error code: 429. Description: Too Many Requests: retry after 5"
2023-06-17 06:10:26,236 (__init__.py:1085 MainThread) ERROR - TeleBot: "Exception traceback:
Traceback (most recent call last):
  File "/home/venv/lib/python3.10/site-packages/telebot/__init__.py", line 1073, in __threaded_polling
    polling_thread.raise_exceptions()
  File "/home/venv/lib/python3.10/site-packages/telebot/util.py", line 109, in raise_exceptions
    raise self.exception_info
  File "/home/venv/lib/python3.10/site-packages/telebot/util.py", line 91, in run
    task(*args, **kwargs)
  File "/home/venv/lib/python3.10/site-packages/telebot/__init__.py", line 649, in __retrieve_updates
    updates = self.get_updates(offset=(self.last_update_id + 1),
  File "/home/venv/lib/python3.10/site-packages/telebot/__init__.py", line 623, in get_updates
    json_updates = apihelper.get_updates(self.token, offset, limit, timeout, allowed_updates, long_polling_timeout)
  File "/home/venv/lib/python3.10/site-packages/telebot/apihelper.py", line 321, in get_updates
    return _make_request(token, method_url, params=payload)
  File "/home/venv/lib/python3.10/site-packages/telebot/apihelper.py", line 162, in _make_request
    json_result = _check_result(method_name, result)
  File "/home/venv/lib/python3.10/site-packages/telebot/apihelper.py", line 189, in _check_result
    raise ApiTelegramException(method_name, result, result_json)
telebot.apihelper.ApiTelegramException: A request to the Telegram API was unsuccessful. Error code: 429. Description: Too Many Requests: retry after 5
"
2023-06-17 06:10:26,785 (__init__.py:1083 MainThread) ERROR - TeleBot: "Threaded polling exception: A request to the Telegram API was unsuccessful. Error code: 429. Description: Too Many Requests: retry after 5"
2023-06-17 06:10:26,787 (__init__.py:1085 MainThread) ERROR - TeleBot: "Exception traceback:
Traceback (most recent call last):
  File "/home/venv/lib/python3.10/site-packages/telebot/__init__.py", line 1073, in __threaded_polling
    polling_thread.raise_exceptions()
  File "/home/venv/lib/python3.10/site-packages/telebot/util.py", line 109, in raise_exceptions
    raise self.exception_info
  File "/home/venv/lib/python3.10/site-packages/telebot/util.py", line 91, in run
    task(*args, **kwargs)
  File "/home/venv/lib/python3.10/site-packages/telebot/__init__.py", line 649, in __retrieve_updates
    updates = self.get_updates(offset=(self.last_update_id + 1),
  File "/home/venv/lib/python3.10/site-packages/telebot/__init__.py", line 623, in get_updates
    json_updates = apihelper.get_updates(self.token, offset, limit, timeout, allowed_updates, long_polling_timeout)
  File "/home/venv/lib/python3.10/site-packages/telebot/apihelper.py", line 321, in get_updates
    return _make_request(token, method_url, params=payload)
  File "/home/venv/lib/python3.10/site-packages/telebot/apihelper.py", line 162, in _make_request
    json_result = _check_result(method_name, result)
  File "/home/venv/lib/python3.10/site-packages/telebot/apihelper.py", line 189, in _check_result
    raise ApiTelegramException(method_name, result, result_json)
telebot.apihelper.ApiTelegramException: A request to the Telegram API was unsuccessful. Error code: 429. Description: Too Many Requests: retry after 5
"
2023-06-17 06:10:29,944 (__init__.py:1083 MainThread) ERROR - TeleBot: "Threaded polling exception: A request to the Telegram API was unsuccessful. Error code: 502. Description: Bad Gateway"
2023-06-17 06:10:29,945 (__init__.py:1085 MainThread) ERROR - TeleBot: "Exception traceback:
Traceback (most recent call last):
  File "/home/venv/lib/python3.10/site-packages/telebot/__init__.py", line 1073, in __threaded_polling
    polling_thread.raise_exceptions()
  File "/home/venv/lib/python3.10/site-packages/telebot/util.py", line 109, in raise_exceptions
    raise self.exception_info
  File "/home/venv/lib/python3.10/site-packages/telebot/util.py", line 91, in run
    task(*args, **kwargs)
  File "/home/venv/lib/python3.10/site-packages/telebot/__init__.py", line 649, in __retrieve_updates
    updates = self.get_updates(offset=(self.last_update_id + 1),
  File "/home/venv/lib/python3.10/site-packages/telebot/__init__.py", line 623, in get_updates
    json_updates = apihelper.get_updates(self.token, offset, limit, timeout, allowed_updates, long_polling_timeout)
  File "/home/venv/lib/python3.10/site-packages/telebot/apihelper.py", line 321, in get_updates
    return _make_request(token, method_url, params=payload)
  File "/home/venv/lib/python3.10/site-packages/telebot/apihelper.py", line 162, in _make_request
    json_result = _check_result(method_name, result)
  File "/home/venv/lib/python3.10/site-packages/telebot/apihelper.py", line 189, in _check_result
    raise ApiTelegramException(method_name, result, result_json)
telebot.apihelper.ApiTelegramException: A request to the Telegram API was unsuccessful. Error code: 502. Description: Bad Gateway
"
2023-06-17 06:10:56,978 (__init__.py:960 MainThread) ERROR - TeleBot: "Infinity polling exception: HTTPSConnectionPool(host='api.telegram.org', port=443): Read timed out. (read timeout=25)"
2023-06-17 06:10:56,979 (__init__.py:962 MainThread) ERROR - TeleBot: "Exception traceback:
Traceback (most recent call last):
  File "/home/venv/lib/python3.10/site-packages/urllib3/connectionpool.py", line 449, in _make_request
    six.raise_from(e, None)
  File "<string>", line 3, in raise_from
  File "/home/venv/lib/python3.10/site-packages/urllib3/connectionpool.py", line 444, in _make_request
    httplib_response = conn.getresponse()
  File "/usr/local/lib/python3.10/http/client.py", line 1374, in getresponse
    response.begin()
  File "/usr/local/lib/python3.10/http/client.py", line 318, in begin
    version, status, reason = self._read_status()
  File "/usr/local/lib/python3.10/http/client.py", line 279, in _read_status
    line = str(self.fp.readline(_MAXLINE + 1), "iso-8859-1")
  File "/usr/local/lib/python3.10/socket.py", line 705, in readinto
    return self._sock.recv_into(b)
  File "/usr/local/lib/python3.10/ssl.py", line 1273, in recv_into
    return self.read(nbytes, buffer)
  File "/usr/local/lib/python3.10/ssl.py", line 1129, in read
    return self._sslobj.read(len, buffer)
TimeoutError: The read operation timed out

During handling of the above exception, another exception occurred:

Traceback (most recent call last):
  File "/home/venv/lib/python3.10/site-packages/requests/adapters.py", line 489, in send
    resp = conn.urlopen(
  File "/home/venv/lib/python3.10/site-packages/urllib3/connectionpool.py", line 787, in urlopen
    retries = retries.increment(
  File "/home/venv/lib/python3.10/site-packages/urllib3/util/retry.py", line 550, in increment
    raise six.reraise(type(error), error, _stacktrace)
  File "/home/venv/lib/python3.10/site-packages/urllib3/packages/six.py", line 770, in reraise
    raise value
  File "/home/venv/lib/python3.10/site-packages/urllib3/connectionpool.py", line 703, in urlopen
    httplib_response = self._make_request(
  File "/home/venv/lib/python3.10/site-packages/urllib3/connectionpool.py", line 451, in _make_request
    self._raise_timeout(err=e, url=url, timeout_value=read_timeout)
  File "/home/venv/lib/python3.10/site-packages/urllib3/connectionpool.py", line 340, in _raise_timeout
    raise ReadTimeoutError(
urllib3.exceptions.ReadTimeoutError: HTTPSConnectionPool(host='api.telegram.org', port=443): Read timed out. (read timeout=25)

During handling of the above exception, another exception occurred:

Traceback (most recent call last):
  File "/home/venv/lib/python3.10/site-packages/telebot/__init__.py", line 955, in infinity_polling
    self.polling(non_stop=True, timeout=timeout, long_polling_timeout=long_polling_timeout,
  File "/home/venv/lib/python3.10/site-packages/telebot/__init__.py", line 1043, in polling
    self.__threaded_polling(non_stop=non_stop, interval=interval, timeout=timeout, long_polling_timeout=long_polling_timeout,
  File "/home/venv/lib/python3.10/site-packages/telebot/__init__.py", line 1118, in __threaded_polling
    raise e
  File "/home/venv/lib/python3.10/site-packages/telebot/__init__.py", line 1073, in __threaded_polling
    polling_thread.raise_exceptions()
  File "/home/venv/lib/python3.10/site-packages/telebot/util.py", line 109, in raise_exceptions
    raise self.exception_info
  File "/home/venv/lib/python3.10/site-packages/telebot/util.py", line 91, in run
    task(*args, **kwargs)
  File "/home/venv/lib/python3.10/site-packages/telebot/__init__.py", line 649, in __retrieve_updates
    updates = self.get_updates(offset=(self.last_update_id + 1),
  File "/home/venv/lib/python3.10/site-packages/telebot/__init__.py", line 623, in get_updates
    json_updates = apihelper.get_updates(self.token, offset, limit, timeout, allowed_updates, long_polling_timeout)
  File "/home/venv/lib/python3.10/site-packages/telebot/apihelper.py", line 321, in get_updates
    return _make_request(token, method_url, params=payload)
  File "/home/venv/lib/python3.10/site-packages/telebot/apihelper.py", line 156, in _make_request
    result = _get_req_session().request(
  File "/home/venv/lib/python3.10/site-packages/requests/sessions.py", line 587, in request
    resp = self.send(prep, **send_kwargs)
  File "/home/venv/lib/python3.10/site-packages/requests/sessions.py", line 701, in send
    r = adapter.send(request, **kwargs)
  File "/home/venv/lib/python3.10/site-packages/requests/adapters.py", line 578, in send
    raise ReadTimeout(e, request=request)
requests.exceptions.ReadTimeout: HTTPSConnectionPool(host='api.telegram.org', port=443): Read timed out. (read timeout=25)
"
2023-06-17 06:11:25,125 (__init__.py:960 MainThread) ERROR - TeleBot: "Infinity polling exception: HTTPSConnectionPool(host='api.telegram.org', port=443): Read timed out. (read timeout=25)"
2023-06-17 06:11:25,126 (__init__.py:962 MainThread) ERROR - TeleBot: "Exception traceback:
Traceback (most recent call last):
  File "/home/venv/lib/python3.10/site-packages/urllib3/connectionpool.py", line 449, in _make_request
    six.raise_from(e, None)
  File "<string>", line 3, in raise_from
  File "/home/venv/lib/python3.10/site-packages/urllib3/connectionpool.py", line 444, in _make_request
    httplib_response = conn.getresponse()
  File "/usr/local/lib/python3.10/http/client.py", line 1374, in getresponse
    response.begin()
  File "/usr/local/lib/python3.10/http/client.py", line 318, in begin
    version, status, reason = self._read_status()
  File "/usr/local/lib/python3.10/http/client.py", line 279, in _read_status
    line = str(self.fp.readline(_MAXLINE + 1), "iso-8859-1")
  File "/usr/local/lib/python3.10/socket.py", line 705, in readinto
    return self._sock.recv_into(b)
  File "/usr/local/lib/python3.10/ssl.py", line 1273, in recv_into
    return self.read(nbytes, buffer)
  File "/usr/local/lib/python3.10/ssl.py", line 1129, in read
    return self._sslobj.read(len, buffer)
TimeoutError: The read operation timed out

During handling of the above exception, another exception occurred:

Traceback (most recent call last):
  File "/home/venv/lib/python3.10/site-packages/requests/adapters.py", line 489, in send
    resp = conn.urlopen(
  File "/home/venv/lib/python3.10/site-packages/urllib3/connectionpool.py", line 787, in urlopen
    retries = retries.increment(
  File "/home/venv/lib/python3.10/site-packages/urllib3/util/retry.py", line 550, in increment
    raise six.reraise(type(error), error, _stacktrace)
  File "/home/venv/lib/python3.10/site-packages/urllib3/packages/six.py", line 770, in reraise
    raise value
  File "/home/venv/lib/python3.10/site-packages/urllib3/connectionpool.py", line 703, in urlopen
    httplib_response = self._make_request(
  File "/home/venv/lib/python3.10/site-packages/urllib3/connectionpool.py", line 451, in _make_request
    self._raise_timeout(err=e, url=url, timeout_value=read_timeout)
  File "/home/venv/lib/python3.10/site-packages/urllib3/connectionpool.py", line 340, in _raise_timeout
    raise ReadTimeoutError(
urllib3.exceptions.ReadTimeoutError: HTTPSConnectionPool(host='api.telegram.org', port=443): Read timed out. (read timeout=25)

During handling of the above exception, another exception occurred:

Traceback (most recent call last):
  File "/home/venv/lib/python3.10/site-packages/telebot/__init__.py", line 955, in infinity_polling
    self.polling(non_stop=True, timeout=timeout, long_polling_timeout=long_polling_timeout,
  File "/home/venv/lib/python3.10/site-packages/telebot/__init__.py", line 1043, in polling
    self.__threaded_polling(non_stop=non_stop, interval=interval, timeout=timeout, long_polling_timeout=long_polling_timeout,
  File "/home/venv/lib/python3.10/site-packages/telebot/__init__.py", line 1118, in __threaded_polling
    raise e
  File "/home/venv/lib/python3.10/site-packages/telebot/__init__.py", line 1073, in __threaded_polling
    polling_thread.raise_exceptions()
  File "/home/venv/lib/python3.10/site-packages/telebot/util.py", line 109, in raise_exceptions
    raise self.exception_info
  File "/home/venv/lib/python3.10/site-packages/telebot/util.py", line 91, in run
    task(*args, **kwargs)
  File "/home/venv/lib/python3.10/site-packages/telebot/__init__.py", line 649, in __retrieve_updates
    updates = self.get_updates(offset=(self.last_update_id + 1),
  File "/home/venv/lib/python3.10/site-packages/telebot/__init__.py", line 623, in get_updates
    json_updates = apihelper.get_updates(self.token, offset, limit, timeout, allowed_updates, long_polling_timeout)
  File "/home/venv/lib/python3.10/site-packages/telebot/apihelper.py", line 321, in get_updates
    return _make_request(token, method_url, params=payload)
  File "/home/venv/lib/python3.10/site-packages/telebot/apihelper.py", line 156, in _make_request
    result = _get_req_session().request(
  File "/home/venv/lib/python3.10/site-packages/requests/sessions.py", line 587, in request
    resp = self.send(prep, **send_kwargs)
  File "/home/venv/lib/python3.10/site-packages/requests/sessions.py", line 701, in send
    r = adapter.send(request, **kwargs)
  File "/home/venv/lib/python3.10/site-packages/requests/adapters.py", line 578, in send
    raise ReadTimeout(e, request=request)
requests.exceptions.ReadTimeout: HTTPSConnectionPool(host='api.telegram.org', port=443): Read timed out. (read timeout=25)
"
{'id': 6278927189, 'is_bot': True, 'first_name': 'Fast Food DEMO', 'username': 'fastfooddemo1bot', 'last_name': None, 'language_code': None, 'can_join_groups': True, 'can_read_all_group_messages': False, 'supports_inline_queries': False, 'is_premium': None, 'added_to_attachment_menu': None}
/home/fast_food_bot/bot/orders.py:50: UnorderedObjectListWarning: Pagination may yield inconsistent results with an unordered object_list: <class 'backend.models.Order'> QuerySet.
  paginator = Paginator(orders, 1)
2023-08-30 21:33:11,220 (__init__.py:960 MainThread) ERROR - TeleBot: "Infinity polling exception: ('Connection aborted.', RemoteDisconnected('Remote end closed connection without response'))"
2023-08-30 21:33:11,222 (__init__.py:962 MainThread) ERROR - TeleBot: "Exception traceback:
Traceback (most recent call last):
  File "/home/venv/lib/python3.10/site-packages/urllib3/connectionpool.py", line 703, in urlopen
    httplib_response = self._make_request(
  File "/home/venv/lib/python3.10/site-packages/urllib3/connectionpool.py", line 449, in _make_request
    six.raise_from(e, None)
  File "<string>", line 3, in raise_from
  File "/home/venv/lib/python3.10/site-packages/urllib3/connectionpool.py", line 444, in _make_request
    httplib_response = conn.getresponse()
  File "/usr/local/lib/python3.10/http/client.py", line 1374, in getresponse
    response.begin()
  File "/usr/local/lib/python3.10/http/client.py", line 318, in begin
    version, status, reason = self._read_status()
  File "/usr/local/lib/python3.10/http/client.py", line 287, in _read_status
    raise RemoteDisconnected("Remote end closed connection without"
http.client.RemoteDisconnected: Remote end closed connection without response

During handling of the above exception, another exception occurred:

Traceback (most recent call last):
  File "/home/venv/lib/python3.10/site-packages/requests/adapters.py", line 489, in send
    resp = conn.urlopen(
  File "/home/venv/lib/python3.10/site-packages/urllib3/connectionpool.py", line 787, in urlopen
    retries = retries.increment(
  File "/home/venv/lib/python3.10/site-packages/urllib3/util/retry.py", line 550, in increment
    raise six.reraise(type(error), error, _stacktrace)
  File "/home/venv/lib/python3.10/site-packages/urllib3/packages/six.py", line 769, in reraise
    raise value.with_traceback(tb)
  File "/home/venv/lib/python3.10/site-packages/urllib3/connectionpool.py", line 703, in urlopen
    httplib_response = self._make_request(
  File "/home/venv/lib/python3.10/site-packages/urllib3/connectionpool.py", line 449, in _make_request
    six.raise_from(e, None)
  File "<string>", line 3, in raise_from
  File "/home/venv/lib/python3.10/site-packages/urllib3/connectionpool.py", line 444, in _make_request
    httplib_response = conn.getresponse()
  File "/usr/local/lib/python3.10/http/client.py", line 1374, in getresponse
    response.begin()
  File "/usr/local/lib/python3.10/http/client.py", line 318, in begin
    version, status, reason = self._read_status()
  File "/usr/local/lib/python3.10/http/client.py", line 287, in _read_status
    raise RemoteDisconnected("Remote end closed connection without"
urllib3.exceptions.ProtocolError: ('Connection aborted.', RemoteDisconnected('Remote end closed connection without response'))

During handling of the above exception, another exception occurred:

Traceback (most recent call last):
  File "/home/venv/lib/python3.10/site-packages/telebot/__init__.py", line 955, in infinity_polling
    self.polling(non_stop=True, timeout=timeout, long_polling_timeout=long_polling_timeout,
  File "/home/venv/lib/python3.10/site-packages/telebot/__init__.py", line 1043, in polling
    self.__threaded_polling(non_stop=non_stop, interval=interval, timeout=timeout, long_polling_timeout=long_polling_timeout,
  File "/home/venv/lib/python3.10/site-packages/telebot/__init__.py", line 1118, in __threaded_polling
    raise e
  File "/home/venv/lib/python3.10/site-packages/telebot/__init__.py", line 1073, in __threaded_polling
    polling_thread.raise_exceptions()
  File "/home/venv/lib/python3.10/site-packages/telebot/util.py", line 109, in raise_exceptions
    raise self.exception_info
  File "/home/venv/lib/python3.10/site-packages/telebot/util.py", line 91, in run
    task(*args, **kwargs)
  File "/home/venv/lib/python3.10/site-packages/telebot/__init__.py", line 649, in __retrieve_updates
    updates = self.get_updates(offset=(self.last_update_id + 1),
  File "/home/venv/lib/python3.10/site-packages/telebot/__init__.py", line 623, in get_updates
    json_updates = apihelper.get_updates(self.token, offset, limit, timeout, allowed_updates, long_polling_timeout)
  File "/home/venv/lib/python3.10/site-packages/telebot/apihelper.py", line 321, in get_updates
    return _make_request(token, method_url, params=payload)
  File "/home/venv/lib/python3.10/site-packages/telebot/apihelper.py", line 156, in _make_request
    result = _get_req_session().request(
  File "/home/venv/lib/python3.10/site-packages/requests/sessions.py", line 587, in request
    resp = self.send(prep, **send_kwargs)
  File "/home/venv/lib/python3.10/site-packages/requests/sessions.py", line 701, in send
    r = adapter.send(request, **kwargs)
  File "/home/venv/lib/python3.10/site-packages/requests/adapters.py", line 547, in send
    raise ConnectionError(err, request=request)
requests.exceptions.ConnectionError: ('Connection aborted.', RemoteDisconnected('Remote end closed connection without response'))
"
2023-08-31 15:49:02,078 (__init__.py:960 MainThread) ERROR - TeleBot: "Infinity polling exception: ('Connection aborted.', RemoteDisconnected('Remote end closed connection without response'))"
2023-08-31 15:49:02,080 (__init__.py:962 MainThread) ERROR - TeleBot: "Exception traceback:
Traceback (most recent call last):
  File "/home/venv/lib/python3.10/site-packages/urllib3/connectionpool.py", line 703, in urlopen
    httplib_response = self._make_request(
  File "/home/venv/lib/python3.10/site-packages/urllib3/connectionpool.py", line 449, in _make_request
    six.raise_from(e, None)
  File "<string>", line 3, in raise_from
  File "/home/venv/lib/python3.10/site-packages/urllib3/connectionpool.py", line 444, in _make_request
    httplib_response = conn.getresponse()
  File "/usr/local/lib/python3.10/http/client.py", line 1374, in getresponse
    response.begin()
  File "/usr/local/lib/python3.10/http/client.py", line 318, in begin
    version, status, reason = self._read_status()
  File "/usr/local/lib/python3.10/http/client.py", line 287, in _read_status
    raise RemoteDisconnected("Remote end closed connection without"
http.client.RemoteDisconnected: Remote end closed connection without response

During handling of the above exception, another exception occurred:

Traceback (most recent call last):
  File "/home/venv/lib/python3.10/site-packages/requests/adapters.py", line 489, in send
    resp = conn.urlopen(
  File "/home/venv/lib/python3.10/site-packages/urllib3/connectionpool.py", line 787, in urlopen
    retries = retries.increment(
  File "/home/venv/lib/python3.10/site-packages/urllib3/util/retry.py", line 550, in increment
    raise six.reraise(type(error), error, _stacktrace)
  File "/home/venv/lib/python3.10/site-packages/urllib3/packages/six.py", line 769, in reraise
    raise value.with_traceback(tb)
  File "/home/venv/lib/python3.10/site-packages/urllib3/connectionpool.py", line 703, in urlopen
    httplib_response = self._make_request(
  File "/home/venv/lib/python3.10/site-packages/urllib3/connectionpool.py", line 449, in _make_request
    six.raise_from(e, None)
  File "<string>", line 3, in raise_from
  File "/home/venv/lib/python3.10/site-packages/urllib3/connectionpool.py", line 444, in _make_request
    httplib_response = conn.getresponse()
  File "/usr/local/lib/python3.10/http/client.py", line 1374, in getresponse
    response.begin()
  File "/usr/local/lib/python3.10/http/client.py", line 318, in begin
    version, status, reason = self._read_status()
  File "/usr/local/lib/python3.10/http/client.py", line 287, in _read_status
    raise RemoteDisconnected("Remote end closed connection without"
urllib3.exceptions.ProtocolError: ('Connection aborted.', RemoteDisconnected('Remote end closed connection without response'))

During handling of the above exception, another exception occurred:

Traceback (most recent call last):
  File "/home/venv/lib/python3.10/site-packages/telebot/__init__.py", line 955, in infinity_polling
    self.polling(non_stop=True, timeout=timeout, long_polling_timeout=long_polling_timeout,
  File "/home/venv/lib/python3.10/site-packages/telebot/__init__.py", line 1043, in polling
    self.__threaded_polling(non_stop=non_stop, interval=interval, timeout=timeout, long_polling_timeout=long_polling_timeout,
  File "/home/venv/lib/python3.10/site-packages/telebot/__init__.py", line 1118, in __threaded_polling
    raise e
  File "/home/venv/lib/python3.10/site-packages/telebot/__init__.py", line 1073, in __threaded_polling
    polling_thread.raise_exceptions()
  File "/home/venv/lib/python3.10/site-packages/telebot/util.py", line 109, in raise_exceptions
    raise self.exception_info
  File "/home/venv/lib/python3.10/site-packages/telebot/util.py", line 91, in run
    task(*args, **kwargs)
  File "/home/venv/lib/python3.10/site-packages/telebot/__init__.py", line 649, in __retrieve_updates
    updates = self.get_updates(offset=(self.last_update_id + 1),
  File "/home/venv/lib/python3.10/site-packages/telebot/__init__.py", line 623, in get_updates
    json_updates = apihelper.get_updates(self.token, offset, limit, timeout, allowed_updates, long_polling_timeout)
  File "/home/venv/lib/python3.10/site-packages/telebot/apihelper.py", line 321, in get_updates
    return _make_request(token, method_url, params=payload)
  File "/home/venv/lib/python3.10/site-packages/telebot/apihelper.py", line 156, in _make_request
    result = _get_req_session().request(
  File "/home/venv/lib/python3.10/site-packages/requests/sessions.py", line 587, in request
    resp = self.send(prep, **send_kwargs)
  File "/home/venv/lib/python3.10/site-packages/requests/sessions.py", line 701, in send
    r = adapter.send(request, **kwargs)
  File "/home/venv/lib/python3.10/site-packages/requests/adapters.py", line 547, in send
    raise ConnectionError(err, request=request)
requests.exceptions.ConnectionError: ('Connection aborted.', RemoteDisconnected('Remote end closed connection without response'))
"
2023-08-31 21:57:25,273 (__init__.py:960 MainThread) ERROR - TeleBot: "Infinity polling exception: ('Connection aborted.', RemoteDisconnected('Remote end closed connection without response'))"
2023-08-31 21:57:25,275 (__init__.py:962 MainThread) ERROR - TeleBot: "Exception traceback:
Traceback (most recent call last):
  File "/home/venv/lib/python3.10/site-packages/urllib3/connectionpool.py", line 703, in urlopen
    httplib_response = self._make_request(
  File "/home/venv/lib/python3.10/site-packages/urllib3/connectionpool.py", line 449, in _make_request
    six.raise_from(e, None)
  File "<string>", line 3, in raise_from
  File "/home/venv/lib/python3.10/site-packages/urllib3/connectionpool.py", line 444, in _make_request
    httplib_response = conn.getresponse()
  File "/usr/local/lib/python3.10/http/client.py", line 1374, in getresponse
    response.begin()
  File "/usr/local/lib/python3.10/http/client.py", line 318, in begin
    version, status, reason = self._read_status()
  File "/usr/local/lib/python3.10/http/client.py", line 287, in _read_status
    raise RemoteDisconnected("Remote end closed connection without"
http.client.RemoteDisconnected: Remote end closed connection without response

During handling of the above exception, another exception occurred:

Traceback (most recent call last):
  File "/home/venv/lib/python3.10/site-packages/requests/adapters.py", line 489, in send
    resp = conn.urlopen(
  File "/home/venv/lib/python3.10/site-packages/urllib3/connectionpool.py", line 787, in urlopen
    retries = retries.increment(
  File "/home/venv/lib/python3.10/site-packages/urllib3/util/retry.py", line 550, in increment
    raise six.reraise(type(error), error, _stacktrace)
  File "/home/venv/lib/python3.10/site-packages/urllib3/packages/six.py", line 769, in reraise
    raise value.with_traceback(tb)
  File "/home/venv/lib/python3.10/site-packages/urllib3/connectionpool.py", line 703, in urlopen
    httplib_response = self._make_request(
  File "/home/venv/lib/python3.10/site-packages/urllib3/connectionpool.py", line 449, in _make_request
    six.raise_from(e, None)
  File "<string>", line 3, in raise_from
  File "/home/venv/lib/python3.10/site-packages/urllib3/connectionpool.py", line 444, in _make_request
    httplib_response = conn.getresponse()
  File "/usr/local/lib/python3.10/http/client.py", line 1374, in getresponse
    response.begin()
  File "/usr/local/lib/python3.10/http/client.py", line 318, in begin
    version, status, reason = self._read_status()
  File "/usr/local/lib/python3.10/http/client.py", line 287, in _read_status
    raise RemoteDisconnected("Remote end closed connection without"
urllib3.exceptions.ProtocolError: ('Connection aborted.', RemoteDisconnected('Remote end closed connection without response'))

During handling of the above exception, another exception occurred:

Traceback (most recent call last):
  File "/home/venv/lib/python3.10/site-packages/telebot/__init__.py", line 955, in infinity_polling
    self.polling(non_stop=True, timeout=timeout, long_polling_timeout=long_polling_timeout,
  File "/home/venv/lib/python3.10/site-packages/telebot/__init__.py", line 1043, in polling
    self.__threaded_polling(non_stop=non_stop, interval=interval, timeout=timeout, long_polling_timeout=long_polling_timeout,
  File "/home/venv/lib/python3.10/site-packages/telebot/__init__.py", line 1118, in __threaded_polling
    raise e
  File "/home/venv/lib/python3.10/site-packages/telebot/__init__.py", line 1073, in __threaded_polling
    polling_thread.raise_exceptions()
  File "/home/venv/lib/python3.10/site-packages/telebot/util.py", line 109, in raise_exceptions
    raise self.exception_info
  File "/home/venv/lib/python3.10/site-packages/telebot/util.py", line 91, in run
    task(*args, **kwargs)
  File "/home/venv/lib/python3.10/site-packages/telebot/__init__.py", line 649, in __retrieve_updates
    updates = self.get_updates(offset=(self.last_update_id + 1),
  File "/home/venv/lib/python3.10/site-packages/telebot/__init__.py", line 623, in get_updates
    json_updates = apihelper.get_updates(self.token, offset, limit, timeout, allowed_updates, long_polling_timeout)
  File "/home/venv/lib/python3.10/site-packages/telebot/apihelper.py", line 321, in get_updates
    return _make_request(token, method_url, params=payload)
  File "/home/venv/lib/python3.10/site-packages/telebot/apihelper.py", line 156, in _make_request
    result = _get_req_session().request(
  File "/home/venv/lib/python3.10/site-packages/requests/sessions.py", line 587, in request
    resp = self.send(prep, **send_kwargs)
  File "/home/venv/lib/python3.10/site-packages/requests/sessions.py", line 701, in send
    r = adapter.send(request, **kwargs)
  File "/home/venv/lib/python3.10/site-packages/requests/adapters.py", line 547, in send
    raise ConnectionError(err, request=request)
requests.exceptions.ConnectionError: ('Connection aborted.', RemoteDisconnected('Remote end closed connection without response'))
"
2023-09-01 03:38:02,907 (__init__.py:960 MainThread) ERROR - TeleBot: "Infinity polling exception: ('Connection aborted.', RemoteDisconnected('Remote end closed connection without response'))"
2023-09-01 03:38:02,912 (__init__.py:962 MainThread) ERROR - TeleBot: "Exception traceback:
Traceback (most recent call last):
  File "/home/venv/lib/python3.10/site-packages/urllib3/connectionpool.py", line 703, in urlopen
    httplib_response = self._make_request(
  File "/home/venv/lib/python3.10/site-packages/urllib3/connectionpool.py", line 449, in _make_request
    six.raise_from(e, None)
  File "<string>", line 3, in raise_from
  File "/home/venv/lib/python3.10/site-packages/urllib3/connectionpool.py", line 444, in _make_request
    httplib_response = conn.getresponse()
  File "/usr/local/lib/python3.10/http/client.py", line 1374, in getresponse
    response.begin()
  File "/usr/local/lib/python3.10/http/client.py", line 318, in begin
    version, status, reason = self._read_status()
  File "/usr/local/lib/python3.10/http/client.py", line 287, in _read_status
    raise RemoteDisconnected("Remote end closed connection without"
http.client.RemoteDisconnected: Remote end closed connection without response

During handling of the above exception, another exception occurred:

Traceback (most recent call last):
  File "/home/venv/lib/python3.10/site-packages/requests/adapters.py", line 489, in send
    resp = conn.urlopen(
  File "/home/venv/lib/python3.10/site-packages/urllib3/connectionpool.py", line 787, in urlopen
    retries = retries.increment(
  File "/home/venv/lib/python3.10/site-packages/urllib3/util/retry.py", line 550, in increment
    raise six.reraise(type(error), error, _stacktrace)
  File "/home/venv/lib/python3.10/site-packages/urllib3/packages/six.py", line 769, in reraise
    raise value.with_traceback(tb)
  File "/home/venv/lib/python3.10/site-packages/urllib3/connectionpool.py", line 703, in urlopen
    httplib_response = self._make_request(
  File "/home/venv/lib/python3.10/site-packages/urllib3/connectionpool.py", line 449, in _make_request
    six.raise_from(e, None)
  File "<string>", line 3, in raise_from
  File "/home/venv/lib/python3.10/site-packages/urllib3/connectionpool.py", line 444, in _make_request
    httplib_response = conn.getresponse()
  File "/usr/local/lib/python3.10/http/client.py", line 1374, in getresponse
    response.begin()
  File "/usr/local/lib/python3.10/http/client.py", line 318, in begin
    version, status, reason = self._read_status()
  File "/usr/local/lib/python3.10/http/client.py", line 287, in _read_status
    raise RemoteDisconnected("Remote end closed connection without"
urllib3.exceptions.ProtocolError: ('Connection aborted.', RemoteDisconnected('Remote end closed connection without response'))

During handling of the above exception, another exception occurred:

Traceback (most recent call last):
  File "/home/venv/lib/python3.10/site-packages/telebot/__init__.py", line 955, in infinity_polling
    self.polling(non_stop=True, timeout=timeout, long_polling_timeout=long_polling_timeout,
  File "/home/venv/lib/python3.10/site-packages/telebot/__init__.py", line 1043, in polling
    self.__threaded_polling(non_stop=non_stop, interval=interval, timeout=timeout, long_polling_timeout=long_polling_timeout,
  File "/home/venv/lib/python3.10/site-packages/telebot/__init__.py", line 1118, in __threaded_polling
    raise e
  File "/home/venv/lib/python3.10/site-packages/telebot/__init__.py", line 1073, in __threaded_polling
    polling_thread.raise_exceptions()
  File "/home/venv/lib/python3.10/site-packages/telebot/util.py", line 109, in raise_exceptions
    raise self.exception_info
  File "/home/venv/lib/python3.10/site-packages/telebot/util.py", line 91, in run
    task(*args, **kwargs)
  File "/home/venv/lib/python3.10/site-packages/telebot/__init__.py", line 649, in __retrieve_updates
    updates = self.get_updates(offset=(self.last_update_id + 1),
  File "/home/venv/lib/python3.10/site-packages/telebot/__init__.py", line 623, in get_updates
    json_updates = apihelper.get_updates(self.token, offset, limit, timeout, allowed_updates, long_polling_timeout)
  File "/home/venv/lib/python3.10/site-packages/telebot/apihelper.py", line 321, in get_updates
    return _make_request(token, method_url, params=payload)
  File "/home/venv/lib/python3.10/site-packages/telebot/apihelper.py", line 156, in _make_request
    result = _get_req_session().request(
  File "/home/venv/lib/python3.10/site-packages/requests/sessions.py", line 587, in request
    resp = self.send(prep, **send_kwargs)
  File "/home/venv/lib/python3.10/site-packages/requests/sessions.py", line 701, in send
    r = adapter.send(request, **kwargs)
  File "/home/venv/lib/python3.10/site-packages/requests/adapters.py", line 547, in send
    raise ConnectionError(err, request=request)
requests.exceptions.ConnectionError: ('Connection aborted.', RemoteDisconnected('Remote end closed connection without response'))
"
2023-09-01 03:38:46,172 (__init__.py:960 MainThread) ERROR - TeleBot: "Infinity polling exception: ('Connection aborted.', RemoteDisconnected('Remote end closed connection without response'))"
2023-09-01 03:38:46,173 (__init__.py:962 MainThread) ERROR - TeleBot: "Exception traceback:
Traceback (most recent call last):
  File "/home/venv/lib/python3.10/site-packages/urllib3/connectionpool.py", line 703, in urlopen
    httplib_response = self._make_request(
  File "/home/venv/lib/python3.10/site-packages/urllib3/connectionpool.py", line 449, in _make_request
    six.raise_from(e, None)
  File "<string>", line 3, in raise_from
  File "/home/venv/lib/python3.10/site-packages/urllib3/connectionpool.py", line 444, in _make_request
    httplib_response = conn.getresponse()
  File "/usr/local/lib/python3.10/http/client.py", line 1374, in getresponse
    response.begin()
  File "/usr/local/lib/python3.10/http/client.py", line 318, in begin
    version, status, reason = self._read_status()
  File "/usr/local/lib/python3.10/http/client.py", line 287, in _read_status
    raise RemoteDisconnected("Remote end closed connection without"
http.client.RemoteDisconnected: Remote end closed connection without response

During handling of the above exception, another exception occurred:

Traceback (most recent call last):
  File "/home/venv/lib/python3.10/site-packages/requests/adapters.py", line 489, in send
    resp = conn.urlopen(
  File "/home/venv/lib/python3.10/site-packages/urllib3/connectionpool.py", line 787, in urlopen
    retries = retries.increment(
  File "/home/venv/lib/python3.10/site-packages/urllib3/util/retry.py", line 550, in increment
    raise six.reraise(type(error), error, _stacktrace)
  File "/home/venv/lib/python3.10/site-packages/urllib3/packages/six.py", line 769, in reraise
    raise value.with_traceback(tb)
  File "/home/venv/lib/python3.10/site-packages/urllib3/connectionpool.py", line 703, in urlopen
    httplib_response = self._make_request(
  File "/home/venv/lib/python3.10/site-packages/urllib3/connectionpool.py", line 449, in _make_request
    six.raise_from(e, None)
  File "<string>", line 3, in raise_from
  File "/home/venv/lib/python3.10/site-packages/urllib3/connectionpool.py", line 444, in _make_request
    httplib_response = conn.getresponse()
  File "/usr/local/lib/python3.10/http/client.py", line 1374, in getresponse
    response.begin()
  File "/usr/local/lib/python3.10/http/client.py", line 318, in begin
    version, status, reason = self._read_status()
  File "/usr/local/lib/python3.10/http/client.py", line 287, in _read_status
    raise RemoteDisconnected("Remote end closed connection without"
urllib3.exceptions.ProtocolError: ('Connection aborted.', RemoteDisconnected('Remote end closed connection without response'))

During handling of the above exception, another exception occurred:

Traceback (most recent call last):
  File "/home/venv/lib/python3.10/site-packages/telebot/__init__.py", line 955, in infinity_polling
    self.polling(non_stop=True, timeout=timeout, long_polling_timeout=long_polling_timeout,
  File "/home/venv/lib/python3.10/site-packages/telebot/__init__.py", line 1043, in polling
    self.__threaded_polling(non_stop=non_stop, interval=interval, timeout=timeout, long_polling_timeout=long_polling_timeout,
  File "/home/venv/lib/python3.10/site-packages/telebot/__init__.py", line 1118, in __threaded_polling
    raise e
  File "/home/venv/lib/python3.10/site-packages/telebot/__init__.py", line 1073, in __threaded_polling
    polling_thread.raise_exceptions()
  File "/home/venv/lib/python3.10/site-packages/telebot/util.py", line 109, in raise_exceptions
    raise self.exception_info
  File "/home/venv/lib/python3.10/site-packages/telebot/util.py", line 91, in run
    task(*args, **kwargs)
  File "/home/venv/lib/python3.10/site-packages/telebot/__init__.py", line 649, in __retrieve_updates
    updates = self.get_updates(offset=(self.last_update_id + 1),
  File "/home/venv/lib/python3.10/site-packages/telebot/__init__.py", line 623, in get_updates
    json_updates = apihelper.get_updates(self.token, offset, limit, timeout, allowed_updates, long_polling_timeout)
  File "/home/venv/lib/python3.10/site-packages/telebot/apihelper.py", line 321, in get_updates
    return _make_request(token, method_url, params=payload)
  File "/home/venv/lib/python3.10/site-packages/telebot/apihelper.py", line 156, in _make_request
    result = _get_req_session().request(
  File "/home/venv/lib/python3.10/site-packages/requests/sessions.py", line 587, in request
    resp = self.send(prep, **send_kwargs)
  File "/home/venv/lib/python3.10/site-packages/requests/sessions.py", line 701, in send
    r = adapter.send(request, **kwargs)
  File "/home/venv/lib/python3.10/site-packages/requests/adapters.py", line 547, in send
    raise ConnectionError(err, request=request)
requests.exceptions.ConnectionError: ('Connection aborted.', RemoteDisconnected('Remote end closed connection without response'))
"
2023-09-01 06:51:18,638 (__init__.py:960 MainThread) ERROR - TeleBot: "Infinity polling exception: ('Connection aborted.', RemoteDisconnected('Remote end closed connection without response'))"
2023-09-01 06:51:18,640 (__init__.py:962 MainThread) ERROR - TeleBot: "Exception traceback:
Traceback (most recent call last):
  File "/home/venv/lib/python3.10/site-packages/urllib3/connectionpool.py", line 703, in urlopen
    httplib_response = self._make_request(
  File "/home/venv/lib/python3.10/site-packages/urllib3/connectionpool.py", line 449, in _make_request
    six.raise_from(e, None)
  File "<string>", line 3, in raise_from
  File "/home/venv/lib/python3.10/site-packages/urllib3/connectionpool.py", line 444, in _make_request
    httplib_response = conn.getresponse()
  File "/usr/local/lib/python3.10/http/client.py", line 1374, in getresponse
    response.begin()
  File "/usr/local/lib/python3.10/http/client.py", line 318, in begin
    version, status, reason = self._read_status()
  File "/usr/local/lib/python3.10/http/client.py", line 287, in _read_status
    raise RemoteDisconnected("Remote end closed connection without"
http.client.RemoteDisconnected: Remote end closed connection without response

During handling of the above exception, another exception occurred:

Traceback (most recent call last):
  File "/home/venv/lib/python3.10/site-packages/requests/adapters.py", line 489, in send
    resp = conn.urlopen(
  File "/home/venv/lib/python3.10/site-packages/urllib3/connectionpool.py", line 787, in urlopen
    retries = retries.increment(
  File "/home/venv/lib/python3.10/site-packages/urllib3/util/retry.py", line 550, in increment
    raise six.reraise(type(error), error, _stacktrace)
  File "/home/venv/lib/python3.10/site-packages/urllib3/packages/six.py", line 769, in reraise
    raise value.with_traceback(tb)
  File "/home/venv/lib/python3.10/site-packages/urllib3/connectionpool.py", line 703, in urlopen
    httplib_response = self._make_request(
  File "/home/venv/lib/python3.10/site-packages/urllib3/connectionpool.py", line 449, in _make_request
    six.raise_from(e, None)
  File "<string>", line 3, in raise_from
  File "/home/venv/lib/python3.10/site-packages/urllib3/connectionpool.py", line 444, in _make_request
    httplib_response = conn.getresponse()
  File "/usr/local/lib/python3.10/http/client.py", line 1374, in getresponse
    response.begin()
  File "/usr/local/lib/python3.10/http/client.py", line 318, in begin
    version, status, reason = self._read_status()
  File "/usr/local/lib/python3.10/http/client.py", line 287, in _read_status
    raise RemoteDisconnected("Remote end closed connection without"
urllib3.exceptions.ProtocolError: ('Connection aborted.', RemoteDisconnected('Remote end closed connection without response'))

During handling of the above exception, another exception occurred:

Traceback (most recent call last):
  File "/home/venv/lib/python3.10/site-packages/telebot/__init__.py", line 955, in infinity_polling
    self.polling(non_stop=True, timeout=timeout, long_polling_timeout=long_polling_timeout,
  File "/home/venv/lib/python3.10/site-packages/telebot/__init__.py", line 1043, in polling
    self.__threaded_polling(non_stop=non_stop, interval=interval, timeout=timeout, long_polling_timeout=long_polling_timeout,
  File "/home/venv/lib/python3.10/site-packages/telebot/__init__.py", line 1118, in __threaded_polling
    raise e
  File "/home/venv/lib/python3.10/site-packages/telebot/__init__.py", line 1073, in __threaded_polling
    polling_thread.raise_exceptions()
  File "/home/venv/lib/python3.10/site-packages/telebot/util.py", line 109, in raise_exceptions
    raise self.exception_info
  File "/home/venv/lib/python3.10/site-packages/telebot/util.py", line 91, in run
    task(*args, **kwargs)
  File "/home/venv/lib/python3.10/site-packages/telebot/__init__.py", line 649, in __retrieve_updates
    updates = self.get_updates(offset=(self.last_update_id + 1),
  File "/home/venv/lib/python3.10/site-packages/telebot/__init__.py", line 623, in get_updates
    json_updates = apihelper.get_updates(self.token, offset, limit, timeout, allowed_updates, long_polling_timeout)
  File "/home/venv/lib/python3.10/site-packages/telebot/apihelper.py", line 321, in get_updates
    return _make_request(token, method_url, params=payload)
  File "/home/venv/lib/python3.10/site-packages/telebot/apihelper.py", line 156, in _make_request
    result = _get_req_session().request(
  File "/home/venv/lib/python3.10/site-packages/requests/sessions.py", line 587, in request
    resp = self.send(prep, **send_kwargs)
  File "/home/venv/lib/python3.10/site-packages/requests/sessions.py", line 701, in send
    r = adapter.send(request, **kwargs)
  File "/home/venv/lib/python3.10/site-packages/requests/adapters.py", line 547, in send
    raise ConnectionError(err, request=request)
requests.exceptions.ConnectionError: ('Connection aborted.', RemoteDisconnected('Remote end closed connection without response'))
"
2023-09-01 08:21:55,709 (__init__.py:960 MainThread) ERROR - TeleBot: "Infinity polling exception: ('Connection aborted.', RemoteDisconnected('Remote end closed connection without response'))"
2023-09-01 08:21:55,711 (__init__.py:962 MainThread) ERROR - TeleBot: "Exception traceback:
Traceback (most recent call last):
  File "/home/venv/lib/python3.10/site-packages/urllib3/connectionpool.py", line 703, in urlopen
    httplib_response = self._make_request(
  File "/home/venv/lib/python3.10/site-packages/urllib3/connectionpool.py", line 449, in _make_request
    six.raise_from(e, None)
  File "<string>", line 3, in raise_from
  File "/home/venv/lib/python3.10/site-packages/urllib3/connectionpool.py", line 444, in _make_request
    httplib_response = conn.getresponse()
  File "/usr/local/lib/python3.10/http/client.py", line 1374, in getresponse
    response.begin()
  File "/usr/local/lib/python3.10/http/client.py", line 318, in begin
    version, status, reason = self._read_status()
  File "/usr/local/lib/python3.10/http/client.py", line 287, in _read_status
    raise RemoteDisconnected("Remote end closed connection without"
http.client.RemoteDisconnected: Remote end closed connection without response

During handling of the above exception, another exception occurred:

Traceback (most recent call last):
  File "/home/venv/lib/python3.10/site-packages/requests/adapters.py", line 489, in send
    resp = conn.urlopen(
  File "/home/venv/lib/python3.10/site-packages/urllib3/connectionpool.py", line 787, in urlopen
    retries = retries.increment(
  File "/home/venv/lib/python3.10/site-packages/urllib3/util/retry.py", line 550, in increment
    raise six.reraise(type(error), error, _stacktrace)
  File "/home/venv/lib/python3.10/site-packages/urllib3/packages/six.py", line 769, in reraise
    raise value.with_traceback(tb)
  File "/home/venv/lib/python3.10/site-packages/urllib3/connectionpool.py", line 703, in urlopen
    httplib_response = self._make_request(
  File "/home/venv/lib/python3.10/site-packages/urllib3/connectionpool.py", line 449, in _make_request
    six.raise_from(e, None)
  File "<string>", line 3, in raise_from
  File "/home/venv/lib/python3.10/site-packages/urllib3/connectionpool.py", line 444, in _make_request
    httplib_response = conn.getresponse()
  File "/usr/local/lib/python3.10/http/client.py", line 1374, in getresponse
    response.begin()
  File "/usr/local/lib/python3.10/http/client.py", line 318, in begin
    version, status, reason = self._read_status()
  File "/usr/local/lib/python3.10/http/client.py", line 287, in _read_status
    raise RemoteDisconnected("Remote end closed connection without"
urllib3.exceptions.ProtocolError: ('Connection aborted.', RemoteDisconnected('Remote end closed connection without response'))

During handling of the above exception, another exception occurred:

Traceback (most recent call last):
  File "/home/venv/lib/python3.10/site-packages/telebot/__init__.py", line 955, in infinity_polling
    self.polling(non_stop=True, timeout=timeout, long_polling_timeout=long_polling_timeout,
  File "/home/venv/lib/python3.10/site-packages/telebot/__init__.py", line 1043, in polling
    self.__threaded_polling(non_stop=non_stop, interval=interval, timeout=timeout, long_polling_timeout=long_polling_timeout,
  File "/home/venv/lib/python3.10/site-packages/telebot/__init__.py", line 1118, in __threaded_polling
    raise e
  File "/home/venv/lib/python3.10/site-packages/telebot/__init__.py", line 1073, in __threaded_polling
    polling_thread.raise_exceptions()
  File "/home/venv/lib/python3.10/site-packages/telebot/util.py", line 109, in raise_exceptions
    raise self.exception_info
  File "/home/venv/lib/python3.10/site-packages/telebot/util.py", line 91, in run
    task(*args, **kwargs)
  File "/home/venv/lib/python3.10/site-packages/telebot/__init__.py", line 649, in __retrieve_updates
    updates = self.get_updates(offset=(self.last_update_id + 1),
  File "/home/venv/lib/python3.10/site-packages/telebot/__init__.py", line 623, in get_updates
    json_updates = apihelper.get_updates(self.token, offset, limit, timeout, allowed_updates, long_polling_timeout)
  File "/home/venv/lib/python3.10/site-packages/telebot/apihelper.py", line 321, in get_updates
    return _make_request(token, method_url, params=payload)
  File "/home/venv/lib/python3.10/site-packages/telebot/apihelper.py", line 156, in _make_request
    result = _get_req_session().request(
  File "/home/venv/lib/python3.10/site-packages/requests/sessions.py", line 587, in request
    resp = self.send(prep, **send_kwargs)
  File "/home/venv/lib/python3.10/site-packages/requests/sessions.py", line 701, in send
    r = adapter.send(request, **kwargs)
  File "/home/venv/lib/python3.10/site-packages/requests/adapters.py", line 547, in send
    raise ConnectionError(err, request=request)
requests.exceptions.ConnectionError: ('Connection aborted.', RemoteDisconnected('Remote end closed connection without response'))
"
2023-09-01 10:22:58,064 (__init__.py:960 MainThread) ERROR - TeleBot: "Infinity polling exception: ('Connection aborted.', RemoteDisconnected('Remote end closed connection without response'))"
2023-09-01 10:22:58,065 (__init__.py:962 MainThread) ERROR - TeleBot: "Exception traceback:
Traceback (most recent call last):
  File "/home/venv/lib/python3.10/site-packages/urllib3/connectionpool.py", line 703, in urlopen
    httplib_response = self._make_request(
  File "/home/venv/lib/python3.10/site-packages/urllib3/connectionpool.py", line 449, in _make_request
    six.raise_from(e, None)
  File "<string>", line 3, in raise_from
  File "/home/venv/lib/python3.10/site-packages/urllib3/connectionpool.py", line 444, in _make_request
    httplib_response = conn.getresponse()
  File "/usr/local/lib/python3.10/http/client.py", line 1374, in getresponse
    response.begin()
  File "/usr/local/lib/python3.10/http/client.py", line 318, in begin
    version, status, reason = self._read_status()
  File "/usr/local/lib/python3.10/http/client.py", line 287, in _read_status
    raise RemoteDisconnected("Remote end closed connection without"
http.client.RemoteDisconnected: Remote end closed connection without response

During handling of the above exception, another exception occurred:

Traceback (most recent call last):
  File "/home/venv/lib/python3.10/site-packages/requests/adapters.py", line 489, in send
    resp = conn.urlopen(
  File "/home/venv/lib/python3.10/site-packages/urllib3/connectionpool.py", line 787, in urlopen
    retries = retries.increment(
  File "/home/venv/lib/python3.10/site-packages/urllib3/util/retry.py", line 550, in increment
    raise six.reraise(type(error), error, _stacktrace)
  File "/home/venv/lib/python3.10/site-packages/urllib3/packages/six.py", line 769, in reraise
    raise value.with_traceback(tb)
  File "/home/venv/lib/python3.10/site-packages/urllib3/connectionpool.py", line 703, in urlopen
    httplib_response = self._make_request(
  File "/home/venv/lib/python3.10/site-packages/urllib3/connectionpool.py", line 449, in _make_request
    six.raise_from(e, None)
  File "<string>", line 3, in raise_from
  File "/home/venv/lib/python3.10/site-packages/urllib3/connectionpool.py", line 444, in _make_request
    httplib_response = conn.getresponse()
  File "/usr/local/lib/python3.10/http/client.py", line 1374, in getresponse
    response.begin()
  File "/usr/local/lib/python3.10/http/client.py", line 318, in begin
    version, status, reason = self._read_status()
  File "/usr/local/lib/python3.10/http/client.py", line 287, in _read_status
    raise RemoteDisconnected("Remote end closed connection without"
urllib3.exceptions.ProtocolError: ('Connection aborted.', RemoteDisconnected('Remote end closed connection without response'))

During handling of the above exception, another exception occurred:

Traceback (most recent call last):
  File "/home/venv/lib/python3.10/site-packages/telebot/__init__.py", line 955, in infinity_polling
    self.polling(non_stop=True, timeout=timeout, long_polling_timeout=long_polling_timeout,
  File "/home/venv/lib/python3.10/site-packages/telebot/__init__.py", line 1043, in polling
    self.__threaded_polling(non_stop=non_stop, interval=interval, timeout=timeout, long_polling_timeout=long_polling_timeout,
  File "/home/venv/lib/python3.10/site-packages/telebot/__init__.py", line 1118, in __threaded_polling
    raise e
  File "/home/venv/lib/python3.10/site-packages/telebot/__init__.py", line 1073, in __threaded_polling
    polling_thread.raise_exceptions()
  File "/home/venv/lib/python3.10/site-packages/telebot/util.py", line 109, in raise_exceptions
    raise self.exception_info
  File "/home/venv/lib/python3.10/site-packages/telebot/util.py", line 91, in run
    task(*args, **kwargs)
  File "/home/venv/lib/python3.10/site-packages/telebot/__init__.py", line 649, in __retrieve_updates
    updates = self.get_updates(offset=(self.last_update_id + 1),
  File "/home/venv/lib/python3.10/site-packages/telebot/__init__.py", line 623, in get_updates
    json_updates = apihelper.get_updates(self.token, offset, limit, timeout, allowed_updates, long_polling_timeout)
  File "/home/venv/lib/python3.10/site-packages/telebot/apihelper.py", line 321, in get_updates
    return _make_request(token, method_url, params=payload)
  File "/home/venv/lib/python3.10/site-packages/telebot/apihelper.py", line 156, in _make_request
    result = _get_req_session().request(
  File "/home/venv/lib/python3.10/site-packages/requests/sessions.py", line 587, in request
    resp = self.send(prep, **send_kwargs)
  File "/home/venv/lib/python3.10/site-packages/requests/sessions.py", line 701, in send
    r = adapter.send(request, **kwargs)
  File "/home/venv/lib/python3.10/site-packages/requests/adapters.py", line 547, in send
    raise ConnectionError(err, request=request)
requests.exceptions.ConnectionError: ('Connection aborted.', RemoteDisconnected('Remote end closed connection without response'))
"
2023-09-01 13:21:49,997 (__init__.py:960 MainThread) ERROR - TeleBot: "Infinity polling exception: ('Connection aborted.', RemoteDisconnected('Remote end closed connection without response'))"
2023-09-01 13:21:49,998 (__init__.py:962 MainThread) ERROR - TeleBot: "Exception traceback:
Traceback (most recent call last):
  File "/home/venv/lib/python3.10/site-packages/urllib3/connectionpool.py", line 703, in urlopen
    httplib_response = self._make_request(
  File "/home/venv/lib/python3.10/site-packages/urllib3/connectionpool.py", line 449, in _make_request
    six.raise_from(e, None)
  File "<string>", line 3, in raise_from
  File "/home/venv/lib/python3.10/site-packages/urllib3/connectionpool.py", line 444, in _make_request
    httplib_response = conn.getresponse()
  File "/usr/local/lib/python3.10/http/client.py", line 1374, in getresponse
    response.begin()
  File "/usr/local/lib/python3.10/http/client.py", line 318, in begin
    version, status, reason = self._read_status()
  File "/usr/local/lib/python3.10/http/client.py", line 287, in _read_status
    raise RemoteDisconnected("Remote end closed connection without"
http.client.RemoteDisconnected: Remote end closed connection without response

During handling of the above exception, another exception occurred:

Traceback (most recent call last):
  File "/home/venv/lib/python3.10/site-packages/requests/adapters.py", line 489, in send
    resp = conn.urlopen(
  File "/home/venv/lib/python3.10/site-packages/urllib3/connectionpool.py", line 787, in urlopen
    retries = retries.increment(
  File "/home/venv/lib/python3.10/site-packages/urllib3/util/retry.py", line 550, in increment
    raise six.reraise(type(error), error, _stacktrace)
  File "/home/venv/lib/python3.10/site-packages/urllib3/packages/six.py", line 769, in reraise
    raise value.with_traceback(tb)
  File "/home/venv/lib/python3.10/site-packages/urllib3/connectionpool.py", line 703, in urlopen
    httplib_response = self._make_request(
  File "/home/venv/lib/python3.10/site-packages/urllib3/connectionpool.py", line 449, in _make_request
    six.raise_from(e, None)
  File "<string>", line 3, in raise_from
  File "/home/venv/lib/python3.10/site-packages/urllib3/connectionpool.py", line 444, in _make_request
    httplib_response = conn.getresponse()
  File "/usr/local/lib/python3.10/http/client.py", line 1374, in getresponse
    response.begin()
  File "/usr/local/lib/python3.10/http/client.py", line 318, in begin
    version, status, reason = self._read_status()
  File "/usr/local/lib/python3.10/http/client.py", line 287, in _read_status
    raise RemoteDisconnected("Remote end closed connection without"
urllib3.exceptions.ProtocolError: ('Connection aborted.', RemoteDisconnected('Remote end closed connection without response'))

During handling of the above exception, another exception occurred:

Traceback (most recent call last):
  File "/home/venv/lib/python3.10/site-packages/telebot/__init__.py", line 955, in infinity_polling
    self.polling(non_stop=True, timeout=timeout, long_polling_timeout=long_polling_timeout,
  File "/home/venv/lib/python3.10/site-packages/telebot/__init__.py", line 1043, in polling
    self.__threaded_polling(non_stop=non_stop, interval=interval, timeout=timeout, long_polling_timeout=long_polling_timeout,
  File "/home/venv/lib/python3.10/site-packages/telebot/__init__.py", line 1118, in __threaded_polling
    raise e
  File "/home/venv/lib/python3.10/site-packages/telebot/__init__.py", line 1073, in __threaded_polling
    polling_thread.raise_exceptions()
  File "/home/venv/lib/python3.10/site-packages/telebot/util.py", line 109, in raise_exceptions
    raise self.exception_info
  File "/home/venv/lib/python3.10/site-packages/telebot/util.py", line 91, in run
    task(*args, **kwargs)
  File "/home/venv/lib/python3.10/site-packages/telebot/__init__.py", line 649, in __retrieve_updates
    updates = self.get_updates(offset=(self.last_update_id + 1),
  File "/home/venv/lib/python3.10/site-packages/telebot/__init__.py", line 623, in get_updates
    json_updates = apihelper.get_updates(self.token, offset, limit, timeout, allowed_updates, long_polling_timeout)
  File "/home/venv/lib/python3.10/site-packages/telebot/apihelper.py", line 321, in get_updates
    return _make_request(token, method_url, params=payload)
  File "/home/venv/lib/python3.10/site-packages/telebot/apihelper.py", line 156, in _make_request
    result = _get_req_session().request(
  File "/home/venv/lib/python3.10/site-packages/requests/sessions.py", line 587, in request
    resp = self.send(prep, **send_kwargs)
  File "/home/venv/lib/python3.10/site-packages/requests/sessions.py", line 701, in send
    r = adapter.send(request, **kwargs)
  File "/home/venv/lib/python3.10/site-packages/requests/adapters.py", line 547, in send
    raise ConnectionError(err, request=request)
requests.exceptions.ConnectionError: ('Connection aborted.', RemoteDisconnected('Remote end closed connection without response'))
"
2023-09-01 18:35:43,918 (__init__.py:960 MainThread) ERROR - TeleBot: "Infinity polling exception: ('Connection aborted.', RemoteDisconnected('Remote end closed connection without response'))"
2023-09-01 18:35:43,919 (__init__.py:962 MainThread) ERROR - TeleBot: "Exception traceback:
Traceback (most recent call last):
  File "/home/venv/lib/python3.10/site-packages/urllib3/connectionpool.py", line 703, in urlopen
    httplib_response = self._make_request(
  File "/home/venv/lib/python3.10/site-packages/urllib3/connectionpool.py", line 449, in _make_request
    six.raise_from(e, None)
  File "<string>", line 3, in raise_from
  File "/home/venv/lib/python3.10/site-packages/urllib3/connectionpool.py", line 444, in _make_request
    httplib_response = conn.getresponse()
  File "/usr/local/lib/python3.10/http/client.py", line 1374, in getresponse
    response.begin()
  File "/usr/local/lib/python3.10/http/client.py", line 318, in begin
    version, status, reason = self._read_status()
  File "/usr/local/lib/python3.10/http/client.py", line 287, in _read_status
    raise RemoteDisconnected("Remote end closed connection without"
http.client.RemoteDisconnected: Remote end closed connection without response

During handling of the above exception, another exception occurred:

Traceback (most recent call last):
  File "/home/venv/lib/python3.10/site-packages/requests/adapters.py", line 489, in send
    resp = conn.urlopen(
  File "/home/venv/lib/python3.10/site-packages/urllib3/connectionpool.py", line 787, in urlopen
    retries = retries.increment(
  File "/home/venv/lib/python3.10/site-packages/urllib3/util/retry.py", line 550, in increment
    raise six.reraise(type(error), error, _stacktrace)
  File "/home/venv/lib/python3.10/site-packages/urllib3/packages/six.py", line 769, in reraise
    raise value.with_traceback(tb)
  File "/home/venv/lib/python3.10/site-packages/urllib3/connectionpool.py", line 703, in urlopen
    httplib_response = self._make_request(
  File "/home/venv/lib/python3.10/site-packages/urllib3/connectionpool.py", line 449, in _make_request
    six.raise_from(e, None)
  File "<string>", line 3, in raise_from
  File "/home/venv/lib/python3.10/site-packages/urllib3/connectionpool.py", line 444, in _make_request
    httplib_response = conn.getresponse()
  File "/usr/local/lib/python3.10/http/client.py", line 1374, in getresponse
    response.begin()
  File "/usr/local/lib/python3.10/http/client.py", line 318, in begin
    version, status, reason = self._read_status()
  File "/usr/local/lib/python3.10/http/client.py", line 287, in _read_status
    raise RemoteDisconnected("Remote end closed connection without"
urllib3.exceptions.ProtocolError: ('Connection aborted.', RemoteDisconnected('Remote end closed connection without response'))

During handling of the above exception, another exception occurred:

Traceback (most recent call last):
  File "/home/venv/lib/python3.10/site-packages/telebot/__init__.py", line 955, in infinity_polling
    self.polling(non_stop=True, timeout=timeout, long_polling_timeout=long_polling_timeout,
  File "/home/venv/lib/python3.10/site-packages/telebot/__init__.py", line 1043, in polling
    self.__threaded_polling(non_stop=non_stop, interval=interval, timeout=timeout, long_polling_timeout=long_polling_timeout,
  File "/home/venv/lib/python3.10/site-packages/telebot/__init__.py", line 1118, in __threaded_polling
    raise e
  File "/home/venv/lib/python3.10/site-packages/telebot/__init__.py", line 1073, in __threaded_polling
    polling_thread.raise_exceptions()
  File "/home/venv/lib/python3.10/site-packages/telebot/util.py", line 109, in raise_exceptions
    raise self.exception_info
  File "/home/venv/lib/python3.10/site-packages/telebot/util.py", line 91, in run
    task(*args, **kwargs)
  File "/home/venv/lib/python3.10/site-packages/telebot/__init__.py", line 649, in __retrieve_updates
    updates = self.get_updates(offset=(self.last_update_id + 1),
  File "/home/venv/lib/python3.10/site-packages/telebot/__init__.py", line 623, in get_updates
    json_updates = apihelper.get_updates(self.token, offset, limit, timeout, allowed_updates, long_polling_timeout)
  File "/home/venv/lib/python3.10/site-packages/telebot/apihelper.py", line 321, in get_updates
    return _make_request(token, method_url, params=payload)
  File "/home/venv/lib/python3.10/site-packages/telebot/apihelper.py", line 156, in _make_request
    result = _get_req_session().request(
  File "/home/venv/lib/python3.10/site-packages/requests/sessions.py", line 587, in request
    resp = self.send(prep, **send_kwargs)
  File "/home/venv/lib/python3.10/site-packages/requests/sessions.py", line 701, in send
    r = adapter.send(request, **kwargs)
  File "/home/venv/lib/python3.10/site-packages/requests/adapters.py", line 547, in send
    raise ConnectionError(err, request=request)
requests.exceptions.ConnectionError: ('Connection aborted.', RemoteDisconnected('Remote end closed connection without response'))
"
2023-09-02 00:42:06,014 (__init__.py:960 MainThread) ERROR - TeleBot: "Infinity polling exception: ('Connection aborted.', RemoteDisconnected('Remote end closed connection without response'))"
2023-09-02 00:42:06,016 (__init__.py:962 MainThread) ERROR - TeleBot: "Exception traceback:
Traceback (most recent call last):
  File "/home/venv/lib/python3.10/site-packages/urllib3/connectionpool.py", line 703, in urlopen
    httplib_response = self._make_request(
  File "/home/venv/lib/python3.10/site-packages/urllib3/connectionpool.py", line 449, in _make_request
    six.raise_from(e, None)
  File "<string>", line 3, in raise_from
  File "/home/venv/lib/python3.10/site-packages/urllib3/connectionpool.py", line 444, in _make_request
    httplib_response = conn.getresponse()
  File "/usr/local/lib/python3.10/http/client.py", line 1374, in getresponse
    response.begin()
  File "/usr/local/lib/python3.10/http/client.py", line 318, in begin
    version, status, reason = self._read_status()
  File "/usr/local/lib/python3.10/http/client.py", line 287, in _read_status
    raise RemoteDisconnected("Remote end closed connection without"
http.client.RemoteDisconnected: Remote end closed connection without response

During handling of the above exception, another exception occurred:

Traceback (most recent call last):
  File "/home/venv/lib/python3.10/site-packages/requests/adapters.py", line 489, in send
    resp = conn.urlopen(
  File "/home/venv/lib/python3.10/site-packages/urllib3/connectionpool.py", line 787, in urlopen
    retries = retries.increment(
  File "/home/venv/lib/python3.10/site-packages/urllib3/util/retry.py", line 550, in increment
    raise six.reraise(type(error), error, _stacktrace)
  File "/home/venv/lib/python3.10/site-packages/urllib3/packages/six.py", line 769, in reraise
    raise value.with_traceback(tb)
  File "/home/venv/lib/python3.10/site-packages/urllib3/connectionpool.py", line 703, in urlopen
    httplib_response = self._make_request(
  File "/home/venv/lib/python3.10/site-packages/urllib3/connectionpool.py", line 449, in _make_request
    six.raise_from(e, None)
  File "<string>", line 3, in raise_from
  File "/home/venv/lib/python3.10/site-packages/urllib3/connectionpool.py", line 444, in _make_request
    httplib_response = conn.getresponse()
  File "/usr/local/lib/python3.10/http/client.py", line 1374, in getresponse
    response.begin()
  File "/usr/local/lib/python3.10/http/client.py", line 318, in begin
    version, status, reason = self._read_status()
  File "/usr/local/lib/python3.10/http/client.py", line 287, in _read_status
    raise RemoteDisconnected("Remote end closed connection without"
urllib3.exceptions.ProtocolError: ('Connection aborted.', RemoteDisconnected('Remote end closed connection without response'))

During handling of the above exception, another exception occurred:

Traceback (most recent call last):
  File "/home/venv/lib/python3.10/site-packages/telebot/__init__.py", line 955, in infinity_polling
    self.polling(non_stop=True, timeout=timeout, long_polling_timeout=long_polling_timeout,
  File "/home/venv/lib/python3.10/site-packages/telebot/__init__.py", line 1043, in polling
    self.__threaded_polling(non_stop=non_stop, interval=interval, timeout=timeout, long_polling_timeout=long_polling_timeout,
  File "/home/venv/lib/python3.10/site-packages/telebot/__init__.py", line 1118, in __threaded_polling
    raise e
  File "/home/venv/lib/python3.10/site-packages/telebot/__init__.py", line 1073, in __threaded_polling
    polling_thread.raise_exceptions()
  File "/home/venv/lib/python3.10/site-packages/telebot/util.py", line 109, in raise_exceptions
    raise self.exception_info
  File "/home/venv/lib/python3.10/site-packages/telebot/util.py", line 91, in run
    task(*args, **kwargs)
  File "/home/venv/lib/python3.10/site-packages/telebot/__init__.py", line 649, in __retrieve_updates
    updates = self.get_updates(offset=(self.last_update_id + 1),
  File "/home/venv/lib/python3.10/site-packages/telebot/__init__.py", line 623, in get_updates
    json_updates = apihelper.get_updates(self.token, offset, limit, timeout, allowed_updates, long_polling_timeout)
  File "/home/venv/lib/python3.10/site-packages/telebot/apihelper.py", line 321, in get_updates
    return _make_request(token, method_url, params=payload)
  File "/home/venv/lib/python3.10/site-packages/telebot/apihelper.py", line 156, in _make_request
    result = _get_req_session().request(
  File "/home/venv/lib/python3.10/site-packages/requests/sessions.py", line 587, in request
    resp = self.send(prep, **send_kwargs)
  File "/home/venv/lib/python3.10/site-packages/requests/sessions.py", line 701, in send
    r = adapter.send(request, **kwargs)
  File "/home/venv/lib/python3.10/site-packages/requests/adapters.py", line 547, in send
    raise ConnectionError(err, request=request)
requests.exceptions.ConnectionError: ('Connection aborted.', RemoteDisconnected('Remote end closed connection without response'))
"
2023-09-02 05:26:33,351 (__init__.py:960 MainThread) ERROR - TeleBot: "Infinity polling exception: ('Connection aborted.', RemoteDisconnected('Remote end closed connection without response'))"
2023-09-02 05:26:33,352 (__init__.py:962 MainThread) ERROR - TeleBot: "Exception traceback:
Traceback (most recent call last):
  File "/home/venv/lib/python3.10/site-packages/urllib3/connectionpool.py", line 703, in urlopen
    httplib_response = self._make_request(
  File "/home/venv/lib/python3.10/site-packages/urllib3/connectionpool.py", line 449, in _make_request
    six.raise_from(e, None)
  File "<string>", line 3, in raise_from
  File "/home/venv/lib/python3.10/site-packages/urllib3/connectionpool.py", line 444, in _make_request
    httplib_response = conn.getresponse()
  File "/usr/local/lib/python3.10/http/client.py", line 1374, in getresponse
    response.begin()
  File "/usr/local/lib/python3.10/http/client.py", line 318, in begin
    version, status, reason = self._read_status()
  File "/usr/local/lib/python3.10/http/client.py", line 287, in _read_status
    raise RemoteDisconnected("Remote end closed connection without"
http.client.RemoteDisconnected: Remote end closed connection without response

During handling of the above exception, another exception occurred:

Traceback (most recent call last):
  File "/home/venv/lib/python3.10/site-packages/requests/adapters.py", line 489, in send
    resp = conn.urlopen(
  File "/home/venv/lib/python3.10/site-packages/urllib3/connectionpool.py", line 787, in urlopen
    retries = retries.increment(
  File "/home/venv/lib/python3.10/site-packages/urllib3/util/retry.py", line 550, in increment
    raise six.reraise(type(error), error, _stacktrace)
  File "/home/venv/lib/python3.10/site-packages/urllib3/packages/six.py", line 769, in reraise
    raise value.with_traceback(tb)
  File "/home/venv/lib/python3.10/site-packages/urllib3/connectionpool.py", line 703, in urlopen
    httplib_response = self._make_request(
  File "/home/venv/lib/python3.10/site-packages/urllib3/connectionpool.py", line 449, in _make_request
    six.raise_from(e, None)
  File "<string>", line 3, in raise_from
  File "/home/venv/lib/python3.10/site-packages/urllib3/connectionpool.py", line 444, in _make_request
    httplib_response = conn.getresponse()
  File "/usr/local/lib/python3.10/http/client.py", line 1374, in getresponse
    response.begin()
  File "/usr/local/lib/python3.10/http/client.py", line 318, in begin
    version, status, reason = self._read_status()
  File "/usr/local/lib/python3.10/http/client.py", line 287, in _read_status
    raise RemoteDisconnected("Remote end closed connection without"
urllib3.exceptions.ProtocolError: ('Connection aborted.', RemoteDisconnected('Remote end closed connection without response'))

During handling of the above exception, another exception occurred:

Traceback (most recent call last):
  File "/home/venv/lib/python3.10/site-packages/telebot/__init__.py", line 955, in infinity_polling
    self.polling(non_stop=True, timeout=timeout, long_polling_timeout=long_polling_timeout,
  File "/home/venv/lib/python3.10/site-packages/telebot/__init__.py", line 1043, in polling
    self.__threaded_polling(non_stop=non_stop, interval=interval, timeout=timeout, long_polling_timeout=long_polling_timeout,
  File "/home/venv/lib/python3.10/site-packages/telebot/__init__.py", line 1118, in __threaded_polling
    raise e
  File "/home/venv/lib/python3.10/site-packages/telebot/__init__.py", line 1073, in __threaded_polling
    polling_thread.raise_exceptions()
  File "/home/venv/lib/python3.10/site-packages/telebot/util.py", line 109, in raise_exceptions
    raise self.exception_info
  File "/home/venv/lib/python3.10/site-packages/telebot/util.py", line 91, in run
    task(*args, **kwargs)
  File "/home/venv/lib/python3.10/site-packages/telebot/__init__.py", line 649, in __retrieve_updates
    updates = self.get_updates(offset=(self.last_update_id + 1),
  File "/home/venv/lib/python3.10/site-packages/telebot/__init__.py", line 623, in get_updates
    json_updates = apihelper.get_updates(self.token, offset, limit, timeout, allowed_updates, long_polling_timeout)
  File "/home/venv/lib/python3.10/site-packages/telebot/apihelper.py", line 321, in get_updates
    return _make_request(token, method_url, params=payload)
  File "/home/venv/lib/python3.10/site-packages/telebot/apihelper.py", line 156, in _make_request
    result = _get_req_session().request(
  File "/home/venv/lib/python3.10/site-packages/requests/sessions.py", line 587, in request
    resp = self.send(prep, **send_kwargs)
  File "/home/venv/lib/python3.10/site-packages/requests/sessions.py", line 701, in send
    r = adapter.send(request, **kwargs)
  File "/home/venv/lib/python3.10/site-packages/requests/adapters.py", line 547, in send
    raise ConnectionError(err, request=request)
requests.exceptions.ConnectionError: ('Connection aborted.', RemoteDisconnected('Remote end closed connection without response'))
"
2023-09-02 05:39:38,369 (__init__.py:960 MainThread) ERROR - TeleBot: "Infinity polling exception: ('Connection aborted.', RemoteDisconnected('Remote end closed connection without response'))"
2023-09-02 05:39:38,371 (__init__.py:962 MainThread) ERROR - TeleBot: "Exception traceback:
Traceback (most recent call last):
  File "/home/venv/lib/python3.10/site-packages/urllib3/connectionpool.py", line 703, in urlopen
    httplib_response = self._make_request(
  File "/home/venv/lib/python3.10/site-packages/urllib3/connectionpool.py", line 449, in _make_request
    six.raise_from(e, None)
  File "<string>", line 3, in raise_from
  File "/home/venv/lib/python3.10/site-packages/urllib3/connectionpool.py", line 444, in _make_request
    httplib_response = conn.getresponse()
  File "/usr/local/lib/python3.10/http/client.py", line 1374, in getresponse
    response.begin()
  File "/usr/local/lib/python3.10/http/client.py", line 318, in begin
    version, status, reason = self._read_status()
  File "/usr/local/lib/python3.10/http/client.py", line 287, in _read_status
    raise RemoteDisconnected("Remote end closed connection without"
http.client.RemoteDisconnected: Remote end closed connection without response

During handling of the above exception, another exception occurred:

Traceback (most recent call last):
  File "/home/venv/lib/python3.10/site-packages/requests/adapters.py", line 489, in send
    resp = conn.urlopen(
  File "/home/venv/lib/python3.10/site-packages/urllib3/connectionpool.py", line 787, in urlopen
    retries = retries.increment(
  File "/home/venv/lib/python3.10/site-packages/urllib3/util/retry.py", line 550, in increment
    raise six.reraise(type(error), error, _stacktrace)
  File "/home/venv/lib/python3.10/site-packages/urllib3/packages/six.py", line 769, in reraise
    raise value.with_traceback(tb)
  File "/home/venv/lib/python3.10/site-packages/urllib3/connectionpool.py", line 703, in urlopen
    httplib_response = self._make_request(
  File "/home/venv/lib/python3.10/site-packages/urllib3/connectionpool.py", line 449, in _make_request
    six.raise_from(e, None)
  File "<string>", line 3, in raise_from
  File "/home/venv/lib/python3.10/site-packages/urllib3/connectionpool.py", line 444, in _make_request
    httplib_response = conn.getresponse()
  File "/usr/local/lib/python3.10/http/client.py", line 1374, in getresponse
    response.begin()
  File "/usr/local/lib/python3.10/http/client.py", line 318, in begin
    version, status, reason = self._read_status()
  File "/usr/local/lib/python3.10/http/client.py", line 287, in _read_status
    raise RemoteDisconnected("Remote end closed connection without"
urllib3.exceptions.ProtocolError: ('Connection aborted.', RemoteDisconnected('Remote end closed connection without response'))

During handling of the above exception, another exception occurred:

Traceback (most recent call last):
  File "/home/venv/lib/python3.10/site-packages/telebot/__init__.py", line 955, in infinity_polling
    self.polling(non_stop=True, timeout=timeout, long_polling_timeout=long_polling_timeout,
  File "/home/venv/lib/python3.10/site-packages/telebot/__init__.py", line 1043, in polling
    self.__threaded_polling(non_stop=non_stop, interval=interval, timeout=timeout, long_polling_timeout=long_polling_timeout,
  File "/home/venv/lib/python3.10/site-packages/telebot/__init__.py", line 1118, in __threaded_polling
    raise e
  File "/home/venv/lib/python3.10/site-packages/telebot/__init__.py", line 1073, in __threaded_polling
    polling_thread.raise_exceptions()
  File "/home/venv/lib/python3.10/site-packages/telebot/util.py", line 109, in raise_exceptions
    raise self.exception_info
  File "/home/venv/lib/python3.10/site-packages/telebot/util.py", line 91, in run
    task(*args, **kwargs)
  File "/home/venv/lib/python3.10/site-packages/telebot/__init__.py", line 649, in __retrieve_updates
    updates = self.get_updates(offset=(self.last_update_id + 1),
  File "/home/venv/lib/python3.10/site-packages/telebot/__init__.py", line 623, in get_updates
    json_updates = apihelper.get_updates(self.token, offset, limit, timeout, allowed_updates, long_polling_timeout)
  File "/home/venv/lib/python3.10/site-packages/telebot/apihelper.py", line 321, in get_updates
    return _make_request(token, method_url, params=payload)
  File "/home/venv/lib/python3.10/site-packages/telebot/apihelper.py", line 156, in _make_request
    result = _get_req_session().request(
  File "/home/venv/lib/python3.10/site-packages/requests/sessions.py", line 587, in request
    resp = self.send(prep, **send_kwargs)
  File "/home/venv/lib/python3.10/site-packages/requests/sessions.py", line 701, in send
    r = adapter.send(request, **kwargs)
  File "/home/venv/lib/python3.10/site-packages/requests/adapters.py", line 547, in send
    raise ConnectionError(err, request=request)
requests.exceptions.ConnectionError: ('Connection aborted.', RemoteDisconnected('Remote end closed connection without response'))
"
2023-09-02 07:34:59,303 (__init__.py:960 MainThread) ERROR - TeleBot: "Infinity polling exception: ('Connection aborted.', RemoteDisconnected('Remote end closed connection without response'))"
2023-09-02 07:34:59,304 (__init__.py:962 MainThread) ERROR - TeleBot: "Exception traceback:
Traceback (most recent call last):
  File "/home/venv/lib/python3.10/site-packages/urllib3/connectionpool.py", line 703, in urlopen
    httplib_response = self._make_request(
  File "/home/venv/lib/python3.10/site-packages/urllib3/connectionpool.py", line 449, in _make_request
    six.raise_from(e, None)
  File "<string>", line 3, in raise_from
  File "/home/venv/lib/python3.10/site-packages/urllib3/connectionpool.py", line 444, in _make_request
    httplib_response = conn.getresponse()
  File "/usr/local/lib/python3.10/http/client.py", line 1374, in getresponse
    response.begin()
  File "/usr/local/lib/python3.10/http/client.py", line 318, in begin
    version, status, reason = self._read_status()
  File "/usr/local/lib/python3.10/http/client.py", line 287, in _read_status
    raise RemoteDisconnected("Remote end closed connection without"
http.client.RemoteDisconnected: Remote end closed connection without response

During handling of the above exception, another exception occurred:

Traceback (most recent call last):
  File "/home/venv/lib/python3.10/site-packages/requests/adapters.py", line 489, in send
    resp = conn.urlopen(
  File "/home/venv/lib/python3.10/site-packages/urllib3/connectionpool.py", line 787, in urlopen
    retries = retries.increment(
  File "/home/venv/lib/python3.10/site-packages/urllib3/util/retry.py", line 550, in increment
    raise six.reraise(type(error), error, _stacktrace)
  File "/home/venv/lib/python3.10/site-packages/urllib3/packages/six.py", line 769, in reraise
    raise value.with_traceback(tb)
  File "/home/venv/lib/python3.10/site-packages/urllib3/connectionpool.py", line 703, in urlopen
    httplib_response = self._make_request(
  File "/home/venv/lib/python3.10/site-packages/urllib3/connectionpool.py", line 449, in _make_request
    six.raise_from(e, None)
  File "<string>", line 3, in raise_from
  File "/home/venv/lib/python3.10/site-packages/urllib3/connectionpool.py", line 444, in _make_request
    httplib_response = conn.getresponse()
  File "/usr/local/lib/python3.10/http/client.py", line 1374, in getresponse
    response.begin()
  File "/usr/local/lib/python3.10/http/client.py", line 318, in begin
    version, status, reason = self._read_status()
  File "/usr/local/lib/python3.10/http/client.py", line 287, in _read_status
    raise RemoteDisconnected("Remote end closed connection without"
urllib3.exceptions.ProtocolError: ('Connection aborted.', RemoteDisconnected('Remote end closed connection without response'))

During handling of the above exception, another exception occurred:

Traceback (most recent call last):
  File "/home/venv/lib/python3.10/site-packages/telebot/__init__.py", line 955, in infinity_polling
    self.polling(non_stop=True, timeout=timeout, long_polling_timeout=long_polling_timeout,
  File "/home/venv/lib/python3.10/site-packages/telebot/__init__.py", line 1043, in polling
    self.__threaded_polling(non_stop=non_stop, interval=interval, timeout=timeout, long_polling_timeout=long_polling_timeout,
  File "/home/venv/lib/python3.10/site-packages/telebot/__init__.py", line 1118, in __threaded_polling
    raise e
  File "/home/venv/lib/python3.10/site-packages/telebot/__init__.py", line 1073, in __threaded_polling
    polling_thread.raise_exceptions()
  File "/home/venv/lib/python3.10/site-packages/telebot/util.py", line 109, in raise_exceptions
    raise self.exception_info
  File "/home/venv/lib/python3.10/site-packages/telebot/util.py", line 91, in run
    task(*args, **kwargs)
  File "/home/venv/lib/python3.10/site-packages/telebot/__init__.py", line 649, in __retrieve_updates
    updates = self.get_updates(offset=(self.last_update_id + 1),
  File "/home/venv/lib/python3.10/site-packages/telebot/__init__.py", line 623, in get_updates
    json_updates = apihelper.get_updates(self.token, offset, limit, timeout, allowed_updates, long_polling_timeout)
  File "/home/venv/lib/python3.10/site-packages/telebot/apihelper.py", line 321, in get_updates
    return _make_request(token, method_url, params=payload)
  File "/home/venv/lib/python3.10/site-packages/telebot/apihelper.py", line 156, in _make_request
    result = _get_req_session().request(
  File "/home/venv/lib/python3.10/site-packages/requests/sessions.py", line 587, in request
    resp = self.send(prep, **send_kwargs)
  File "/home/venv/lib/python3.10/site-packages/requests/sessions.py", line 701, in send
    r = adapter.send(request, **kwargs)
  File "/home/venv/lib/python3.10/site-packages/requests/adapters.py", line 547, in send
    raise ConnectionError(err, request=request)
requests.exceptions.ConnectionError: ('Connection aborted.', RemoteDisconnected('Remote end closed connection without response'))
"
2023-09-02 10:46:51,790 (__init__.py:960 MainThread) ERROR - TeleBot: "Infinity polling exception: ('Connection aborted.', RemoteDisconnected('Remote end closed connection without response'))"
2023-09-02 10:46:51,791 (__init__.py:962 MainThread) ERROR - TeleBot: "Exception traceback:
Traceback (most recent call last):
  File "/home/venv/lib/python3.10/site-packages/urllib3/connectionpool.py", line 703, in urlopen
    httplib_response = self._make_request(
  File "/home/venv/lib/python3.10/site-packages/urllib3/connectionpool.py", line 449, in _make_request
    six.raise_from(e, None)
  File "<string>", line 3, in raise_from
  File "/home/venv/lib/python3.10/site-packages/urllib3/connectionpool.py", line 444, in _make_request
    httplib_response = conn.getresponse()
  File "/usr/local/lib/python3.10/http/client.py", line 1374, in getresponse
    response.begin()
  File "/usr/local/lib/python3.10/http/client.py", line 318, in begin
    version, status, reason = self._read_status()
  File "/usr/local/lib/python3.10/http/client.py", line 287, in _read_status
    raise RemoteDisconnected("Remote end closed connection without"
http.client.RemoteDisconnected: Remote end closed connection without response

During handling of the above exception, another exception occurred:

Traceback (most recent call last):
  File "/home/venv/lib/python3.10/site-packages/requests/adapters.py", line 489, in send
    resp = conn.urlopen(
  File "/home/venv/lib/python3.10/site-packages/urllib3/connectionpool.py", line 787, in urlopen
    retries = retries.increment(
  File "/home/venv/lib/python3.10/site-packages/urllib3/util/retry.py", line 550, in increment
    raise six.reraise(type(error), error, _stacktrace)
  File "/home/venv/lib/python3.10/site-packages/urllib3/packages/six.py", line 769, in reraise
    raise value.with_traceback(tb)
  File "/home/venv/lib/python3.10/site-packages/urllib3/connectionpool.py", line 703, in urlopen
    httplib_response = self._make_request(
  File "/home/venv/lib/python3.10/site-packages/urllib3/connectionpool.py", line 449, in _make_request
    six.raise_from(e, None)
  File "<string>", line 3, in raise_from
  File "/home/venv/lib/python3.10/site-packages/urllib3/connectionpool.py", line 444, in _make_request
    httplib_response = conn.getresponse()
  File "/usr/local/lib/python3.10/http/client.py", line 1374, in getresponse
    response.begin()
  File "/usr/local/lib/python3.10/http/client.py", line 318, in begin
    version, status, reason = self._read_status()
  File "/usr/local/lib/python3.10/http/client.py", line 287, in _read_status
    raise RemoteDisconnected("Remote end closed connection without"
urllib3.exceptions.ProtocolError: ('Connection aborted.', RemoteDisconnected('Remote end closed connection without response'))

During handling of the above exception, another exception occurred:

Traceback (most recent call last):
  File "/home/venv/lib/python3.10/site-packages/telebot/__init__.py", line 955, in infinity_polling
    self.polling(non_stop=True, timeout=timeout, long_polling_timeout=long_polling_timeout,
  File "/home/venv/lib/python3.10/site-packages/telebot/__init__.py", line 1043, in polling
    self.__threaded_polling(non_stop=non_stop, interval=interval, timeout=timeout, long_polling_timeout=long_polling_timeout,
  File "/home/venv/lib/python3.10/site-packages/telebot/__init__.py", line 1118, in __threaded_polling
    raise e
  File "/home/venv/lib/python3.10/site-packages/telebot/__init__.py", line 1073, in __threaded_polling
    polling_thread.raise_exceptions()
  File "/home/venv/lib/python3.10/site-packages/telebot/util.py", line 109, in raise_exceptions
    raise self.exception_info
  File "/home/venv/lib/python3.10/site-packages/telebot/util.py", line 91, in run
    task(*args, **kwargs)
  File "/home/venv/lib/python3.10/site-packages/telebot/__init__.py", line 649, in __retrieve_updates
    updates = self.get_updates(offset=(self.last_update_id + 1),
  File "/home/venv/lib/python3.10/site-packages/telebot/__init__.py", line 623, in get_updates
    json_updates = apihelper.get_updates(self.token, offset, limit, timeout, allowed_updates, long_polling_timeout)
  File "/home/venv/lib/python3.10/site-packages/telebot/apihelper.py", line 321, in get_updates
    return _make_request(token, method_url, params=payload)
  File "/home/venv/lib/python3.10/site-packages/telebot/apihelper.py", line 156, in _make_request
    result = _get_req_session().request(
  File "/home/venv/lib/python3.10/site-packages/requests/sessions.py", line 587, in request
    resp = self.send(prep, **send_kwargs)
  File "/home/venv/lib/python3.10/site-packages/requests/sessions.py", line 701, in send
    r = adapter.send(request, **kwargs)
  File "/home/venv/lib/python3.10/site-packages/requests/adapters.py", line 547, in send
    raise ConnectionError(err, request=request)
requests.exceptions.ConnectionError: ('Connection aborted.', RemoteDisconnected('Remote end closed connection without response'))
"
2023-09-02 21:15:16,676 (__init__.py:1083 MainThread) ERROR - TeleBot: "Threaded polling exception: A request to the Telegram API was unsuccessful. Error code: 502. Description: Bad Gateway"
2023-09-02 21:15:16,677 (__init__.py:1085 MainThread) ERROR - TeleBot: "Exception traceback:
Traceback (most recent call last):
  File "/home/venv/lib/python3.10/site-packages/telebot/__init__.py", line 1073, in __threaded_polling
    polling_thread.raise_exceptions()
  File "/home/venv/lib/python3.10/site-packages/telebot/util.py", line 109, in raise_exceptions
    raise self.exception_info
  File "/home/venv/lib/python3.10/site-packages/telebot/util.py", line 91, in run
    task(*args, **kwargs)
  File "/home/venv/lib/python3.10/site-packages/telebot/__init__.py", line 649, in __retrieve_updates
    updates = self.get_updates(offset=(self.last_update_id + 1),
  File "/home/venv/lib/python3.10/site-packages/telebot/__init__.py", line 623, in get_updates
    json_updates = apihelper.get_updates(self.token, offset, limit, timeout, allowed_updates, long_polling_timeout)
  File "/home/venv/lib/python3.10/site-packages/telebot/apihelper.py", line 321, in get_updates
    return _make_request(token, method_url, params=payload)
  File "/home/venv/lib/python3.10/site-packages/telebot/apihelper.py", line 162, in _make_request
    json_result = _check_result(method_name, result)
  File "/home/venv/lib/python3.10/site-packages/telebot/apihelper.py", line 189, in _check_result
    raise ApiTelegramException(method_name, result, result_json)
telebot.apihelper.ApiTelegramException: A request to the Telegram API was unsuccessful. Error code: 502. Description: Bad Gateway
"
2023-09-02 21:15:16,976 (__init__.py:1083 MainThread) ERROR - TeleBot: "Threaded polling exception: A request to the Telegram API was unsuccessful. Error code: 502. Description: Bad Gateway"
2023-09-02 21:15:16,976 (__init__.py:1085 MainThread) ERROR - TeleBot: "Exception traceback:
Traceback (most recent call last):
  File "/home/venv/lib/python3.10/site-packages/telebot/__init__.py", line 1073, in __threaded_polling
    polling_thread.raise_exceptions()
  File "/home/venv/lib/python3.10/site-packages/telebot/util.py", line 109, in raise_exceptions
    raise self.exception_info
  File "/home/venv/lib/python3.10/site-packages/telebot/util.py", line 91, in run
    task(*args, **kwargs)
  File "/home/venv/lib/python3.10/site-packages/telebot/__init__.py", line 649, in __retrieve_updates
    updates = self.get_updates(offset=(self.last_update_id + 1),
  File "/home/venv/lib/python3.10/site-packages/telebot/__init__.py", line 623, in get_updates
    json_updates = apihelper.get_updates(self.token, offset, limit, timeout, allowed_updates, long_polling_timeout)
  File "/home/venv/lib/python3.10/site-packages/telebot/apihelper.py", line 321, in get_updates
    return _make_request(token, method_url, params=payload)
  File "/home/venv/lib/python3.10/site-packages/telebot/apihelper.py", line 162, in _make_request
    json_result = _check_result(method_name, result)
  File "/home/venv/lib/python3.10/site-packages/telebot/apihelper.py", line 189, in _check_result
    raise ApiTelegramException(method_name, result, result_json)
telebot.apihelper.ApiTelegramException: A request to the Telegram API was unsuccessful. Error code: 502. Description: Bad Gateway
"
2023-09-02 21:15:17,523 (__init__.py:1083 MainThread) ERROR - TeleBot: "Threaded polling exception: A request to the Telegram API was unsuccessful. Error code: 502. Description: Bad Gateway"
2023-09-02 21:15:17,524 (__init__.py:1085 MainThread) ERROR - TeleBot: "Exception traceback:
Traceback (most recent call last):
  File "/home/venv/lib/python3.10/site-packages/telebot/__init__.py", line 1073, in __threaded_polling
    polling_thread.raise_exceptions()
  File "/home/venv/lib/python3.10/site-packages/telebot/util.py", line 109, in raise_exceptions
    raise self.exception_info
  File "/home/venv/lib/python3.10/site-packages/telebot/util.py", line 91, in run
    task(*args, **kwargs)
  File "/home/venv/lib/python3.10/site-packages/telebot/__init__.py", line 649, in __retrieve_updates
    updates = self.get_updates(offset=(self.last_update_id + 1),
  File "/home/venv/lib/python3.10/site-packages/telebot/__init__.py", line 623, in get_updates
    json_updates = apihelper.get_updates(self.token, offset, limit, timeout, allowed_updates, long_polling_timeout)
  File "/home/venv/lib/python3.10/site-packages/telebot/apihelper.py", line 321, in get_updates
    return _make_request(token, method_url, params=payload)
  File "/home/venv/lib/python3.10/site-packages/telebot/apihelper.py", line 162, in _make_request
    json_result = _check_result(method_name, result)
  File "/home/venv/lib/python3.10/site-packages/telebot/apihelper.py", line 189, in _check_result
    raise ApiTelegramException(method_name, result, result_json)
telebot.apihelper.ApiTelegramException: A request to the Telegram API was unsuccessful. Error code: 502. Description: Bad Gateway
"
2023-09-02 21:15:43,546 (__init__.py:960 MainThread) ERROR - TeleBot: "Infinity polling exception: HTTPSConnectionPool(host='api.telegram.org', port=443): Read timed out. (read timeout=25)"
2023-09-02 21:15:43,547 (__init__.py:962 MainThread) ERROR - TeleBot: "Exception traceback:
Traceback (most recent call last):
  File "/home/venv/lib/python3.10/site-packages/urllib3/connectionpool.py", line 449, in _make_request
    six.raise_from(e, None)
  File "<string>", line 3, in raise_from
  File "/home/venv/lib/python3.10/site-packages/urllib3/connectionpool.py", line 444, in _make_request
    httplib_response = conn.getresponse()
  File "/usr/local/lib/python3.10/http/client.py", line 1374, in getresponse
    response.begin()
  File "/usr/local/lib/python3.10/http/client.py", line 318, in begin
    version, status, reason = self._read_status()
  File "/usr/local/lib/python3.10/http/client.py", line 279, in _read_status
    line = str(self.fp.readline(_MAXLINE + 1), "iso-8859-1")
  File "/usr/local/lib/python3.10/socket.py", line 705, in readinto
    return self._sock.recv_into(b)
  File "/usr/local/lib/python3.10/ssl.py", line 1273, in recv_into
    return self.read(nbytes, buffer)
  File "/usr/local/lib/python3.10/ssl.py", line 1129, in read
    return self._sslobj.read(len, buffer)
TimeoutError: The read operation timed out

During handling of the above exception, another exception occurred:

Traceback (most recent call last):
  File "/home/venv/lib/python3.10/site-packages/requests/adapters.py", line 489, in send
    resp = conn.urlopen(
  File "/home/venv/lib/python3.10/site-packages/urllib3/connectionpool.py", line 787, in urlopen
    retries = retries.increment(
  File "/home/venv/lib/python3.10/site-packages/urllib3/util/retry.py", line 550, in increment
    raise six.reraise(type(error), error, _stacktrace)
  File "/home/venv/lib/python3.10/site-packages/urllib3/packages/six.py", line 770, in reraise
    raise value
  File "/home/venv/lib/python3.10/site-packages/urllib3/connectionpool.py", line 703, in urlopen
    httplib_response = self._make_request(
  File "/home/venv/lib/python3.10/site-packages/urllib3/connectionpool.py", line 451, in _make_request
    self._raise_timeout(err=e, url=url, timeout_value=read_timeout)
  File "/home/venv/lib/python3.10/site-packages/urllib3/connectionpool.py", line 340, in _raise_timeout
    raise ReadTimeoutError(
urllib3.exceptions.ReadTimeoutError: HTTPSConnectionPool(host='api.telegram.org', port=443): Read timed out. (read timeout=25)

During handling of the above exception, another exception occurred:

Traceback (most recent call last):
  File "/home/venv/lib/python3.10/site-packages/telebot/__init__.py", line 955, in infinity_polling
    self.polling(non_stop=True, timeout=timeout, long_polling_timeout=long_polling_timeout,
  File "/home/venv/lib/python3.10/site-packages/telebot/__init__.py", line 1043, in polling
    self.__threaded_polling(non_stop=non_stop, interval=interval, timeout=timeout, long_polling_timeout=long_polling_timeout,
  File "/home/venv/lib/python3.10/site-packages/telebot/__init__.py", line 1118, in __threaded_polling
    raise e
  File "/home/venv/lib/python3.10/site-packages/telebot/__init__.py", line 1073, in __threaded_polling
    polling_thread.raise_exceptions()
  File "/home/venv/lib/python3.10/site-packages/telebot/util.py", line 109, in raise_exceptions
    raise self.exception_info
  File "/home/venv/lib/python3.10/site-packages/telebot/util.py", line 91, in run
    task(*args, **kwargs)
  File "/home/venv/lib/python3.10/site-packages/telebot/__init__.py", line 649, in __retrieve_updates
    updates = self.get_updates(offset=(self.last_update_id + 1),
  File "/home/venv/lib/python3.10/site-packages/telebot/__init__.py", line 623, in get_updates
    json_updates = apihelper.get_updates(self.token, offset, limit, timeout, allowed_updates, long_polling_timeout)
  File "/home/venv/lib/python3.10/site-packages/telebot/apihelper.py", line 321, in get_updates
    return _make_request(token, method_url, params=payload)
  File "/home/venv/lib/python3.10/site-packages/telebot/apihelper.py", line 156, in _make_request
    result = _get_req_session().request(
  File "/home/venv/lib/python3.10/site-packages/requests/sessions.py", line 587, in request
    resp = self.send(prep, **send_kwargs)
  File "/home/venv/lib/python3.10/site-packages/requests/sessions.py", line 701, in send
    r = adapter.send(request, **kwargs)
  File "/home/venv/lib/python3.10/site-packages/requests/adapters.py", line 578, in send
    raise ReadTimeout(e, request=request)
requests.exceptions.ReadTimeout: HTTPSConnectionPool(host='api.telegram.org', port=443): Read timed out. (read timeout=25)
"
2023-09-02 21:16:11,701 (__init__.py:960 MainThread) ERROR - TeleBot: "Infinity polling exception: HTTPSConnectionPool(host='api.telegram.org', port=443): Read timed out. (read timeout=25)"
2023-09-02 21:16:11,703 (__init__.py:962 MainThread) ERROR - TeleBot: "Exception traceback:
Traceback (most recent call last):
  File "/home/venv/lib/python3.10/site-packages/urllib3/connectionpool.py", line 449, in _make_request
    six.raise_from(e, None)
  File "<string>", line 3, in raise_from
  File "/home/venv/lib/python3.10/site-packages/urllib3/connectionpool.py", line 444, in _make_request
    httplib_response = conn.getresponse()
  File "/usr/local/lib/python3.10/http/client.py", line 1374, in getresponse
    response.begin()
  File "/usr/local/lib/python3.10/http/client.py", line 318, in begin
    version, status, reason = self._read_status()
  File "/usr/local/lib/python3.10/http/client.py", line 279, in _read_status
    line = str(self.fp.readline(_MAXLINE + 1), "iso-8859-1")
  File "/usr/local/lib/python3.10/socket.py", line 705, in readinto
    return self._sock.recv_into(b)
  File "/usr/local/lib/python3.10/ssl.py", line 1273, in recv_into
    return self.read(nbytes, buffer)
  File "/usr/local/lib/python3.10/ssl.py", line 1129, in read
    return self._sslobj.read(len, buffer)
TimeoutError: The read operation timed out

During handling of the above exception, another exception occurred:

Traceback (most recent call last):
  File "/home/venv/lib/python3.10/site-packages/requests/adapters.py", line 489, in send
    resp = conn.urlopen(
  File "/home/venv/lib/python3.10/site-packages/urllib3/connectionpool.py", line 787, in urlopen
    retries = retries.increment(
  File "/home/venv/lib/python3.10/site-packages/urllib3/util/retry.py", line 550, in increment
    raise six.reraise(type(error), error, _stacktrace)
  File "/home/venv/lib/python3.10/site-packages/urllib3/packages/six.py", line 770, in reraise
    raise value
  File "/home/venv/lib/python3.10/site-packages/urllib3/connectionpool.py", line 703, in urlopen
    httplib_response = self._make_request(
  File "/home/venv/lib/python3.10/site-packages/urllib3/connectionpool.py", line 451, in _make_request
    self._raise_timeout(err=e, url=url, timeout_value=read_timeout)
  File "/home/venv/lib/python3.10/site-packages/urllib3/connectionpool.py", line 340, in _raise_timeout
    raise ReadTimeoutError(
urllib3.exceptions.ReadTimeoutError: HTTPSConnectionPool(host='api.telegram.org', port=443): Read timed out. (read timeout=25)

During handling of the above exception, another exception occurred:

Traceback (most recent call last):
  File "/home/venv/lib/python3.10/site-packages/telebot/__init__.py", line 955, in infinity_polling
    self.polling(non_stop=True, timeout=timeout, long_polling_timeout=long_polling_timeout,
  File "/home/venv/lib/python3.10/site-packages/telebot/__init__.py", line 1043, in polling
    self.__threaded_polling(non_stop=non_stop, interval=interval, timeout=timeout, long_polling_timeout=long_polling_timeout,
  File "/home/venv/lib/python3.10/site-packages/telebot/__init__.py", line 1118, in __threaded_polling
    raise e
  File "/home/venv/lib/python3.10/site-packages/telebot/__init__.py", line 1073, in __threaded_polling
    polling_thread.raise_exceptions()
  File "/home/venv/lib/python3.10/site-packages/telebot/util.py", line 109, in raise_exceptions
    raise self.exception_info
  File "/home/venv/lib/python3.10/site-packages/telebot/util.py", line 91, in run
    task(*args, **kwargs)
  File "/home/venv/lib/python3.10/site-packages/telebot/__init__.py", line 649, in __retrieve_updates
    updates = self.get_updates(offset=(self.last_update_id + 1),
  File "/home/venv/lib/python3.10/site-packages/telebot/__init__.py", line 623, in get_updates
    json_updates = apihelper.get_updates(self.token, offset, limit, timeout, allowed_updates, long_polling_timeout)
  File "/home/venv/lib/python3.10/site-packages/telebot/apihelper.py", line 321, in get_updates
    return _make_request(token, method_url, params=payload)
  File "/home/venv/lib/python3.10/site-packages/telebot/apihelper.py", line 156, in _make_request
    result = _get_req_session().request(
  File "/home/venv/lib/python3.10/site-packages/requests/sessions.py", line 587, in request
    resp = self.send(prep, **send_kwargs)
  File "/home/venv/lib/python3.10/site-packages/requests/sessions.py", line 701, in send
    r = adapter.send(request, **kwargs)
  File "/home/venv/lib/python3.10/site-packages/requests/adapters.py", line 578, in send
    raise ReadTimeout(e, request=request)
requests.exceptions.ReadTimeout: HTTPSConnectionPool(host='api.telegram.org', port=443): Read timed out. (read timeout=25)
"
2023-09-03 07:31:11,296 (__init__.py:960 MainThread) ERROR - TeleBot: "Infinity polling exception: ('Connection aborted.', RemoteDisconnected('Remote end closed connection without response'))"
2023-09-03 07:31:11,298 (__init__.py:962 MainThread) ERROR - TeleBot: "Exception traceback:
Traceback (most recent call last):
  File "/home/venv/lib/python3.10/site-packages/urllib3/connectionpool.py", line 703, in urlopen
    httplib_response = self._make_request(
  File "/home/venv/lib/python3.10/site-packages/urllib3/connectionpool.py", line 449, in _make_request
    six.raise_from(e, None)
  File "<string>", line 3, in raise_from
  File "/home/venv/lib/python3.10/site-packages/urllib3/connectionpool.py", line 444, in _make_request
    httplib_response = conn.getresponse()
  File "/usr/local/lib/python3.10/http/client.py", line 1374, in getresponse
    response.begin()
  File "/usr/local/lib/python3.10/http/client.py", line 318, in begin
    version, status, reason = self._read_status()
  File "/usr/local/lib/python3.10/http/client.py", line 287, in _read_status
    raise RemoteDisconnected("Remote end closed connection without"
http.client.RemoteDisconnected: Remote end closed connection without response

During handling of the above exception, another exception occurred:

Traceback (most recent call last):
  File "/home/venv/lib/python3.10/site-packages/requests/adapters.py", line 489, in send
    resp = conn.urlopen(
  File "/home/venv/lib/python3.10/site-packages/urllib3/connectionpool.py", line 787, in urlopen
    retries = retries.increment(
  File "/home/venv/lib/python3.10/site-packages/urllib3/util/retry.py", line 550, in increment
    raise six.reraise(type(error), error, _stacktrace)
  File "/home/venv/lib/python3.10/site-packages/urllib3/packages/six.py", line 769, in reraise
    raise value.with_traceback(tb)
  File "/home/venv/lib/python3.10/site-packages/urllib3/connectionpool.py", line 703, in urlopen
    httplib_response = self._make_request(
  File "/home/venv/lib/python3.10/site-packages/urllib3/connectionpool.py", line 449, in _make_request
    six.raise_from(e, None)
  File "<string>", line 3, in raise_from
  File "/home/venv/lib/python3.10/site-packages/urllib3/connectionpool.py", line 444, in _make_request
    httplib_response = conn.getresponse()
  File "/usr/local/lib/python3.10/http/client.py", line 1374, in getresponse
    response.begin()
  File "/usr/local/lib/python3.10/http/client.py", line 318, in begin
    version, status, reason = self._read_status()
  File "/usr/local/lib/python3.10/http/client.py", line 287, in _read_status
    raise RemoteDisconnected("Remote end closed connection without"
urllib3.exceptions.ProtocolError: ('Connection aborted.', RemoteDisconnected('Remote end closed connection without response'))

During handling of the above exception, another exception occurred:

Traceback (most recent call last):
  File "/home/venv/lib/python3.10/site-packages/telebot/__init__.py", line 955, in infinity_polling
    self.polling(non_stop=True, timeout=timeout, long_polling_timeout=long_polling_timeout,
  File "/home/venv/lib/python3.10/site-packages/telebot/__init__.py", line 1043, in polling
    self.__threaded_polling(non_stop=non_stop, interval=interval, timeout=timeout, long_polling_timeout=long_polling_timeout,
  File "/home/venv/lib/python3.10/site-packages/telebot/__init__.py", line 1118, in __threaded_polling
    raise e
  File "/home/venv/lib/python3.10/site-packages/telebot/__init__.py", line 1073, in __threaded_polling
    polling_thread.raise_exceptions()
  File "/home/venv/lib/python3.10/site-packages/telebot/util.py", line 109, in raise_exceptions
    raise self.exception_info
  File "/home/venv/lib/python3.10/site-packages/telebot/util.py", line 91, in run
    task(*args, **kwargs)
  File "/home/venv/lib/python3.10/site-packages/telebot/__init__.py", line 649, in __retrieve_updates
    updates = self.get_updates(offset=(self.last_update_id + 1),
  File "/home/venv/lib/python3.10/site-packages/telebot/__init__.py", line 623, in get_updates
    json_updates = apihelper.get_updates(self.token, offset, limit, timeout, allowed_updates, long_polling_timeout)
  File "/home/venv/lib/python3.10/site-packages/telebot/apihelper.py", line 321, in get_updates
    return _make_request(token, method_url, params=payload)
  File "/home/venv/lib/python3.10/site-packages/telebot/apihelper.py", line 156, in _make_request
    result = _get_req_session().request(
  File "/home/venv/lib/python3.10/site-packages/requests/sessions.py", line 587, in request
    resp = self.send(prep, **send_kwargs)
  File "/home/venv/lib/python3.10/site-packages/requests/sessions.py", line 701, in send
    r = adapter.send(request, **kwargs)
  File "/home/venv/lib/python3.10/site-packages/requests/adapters.py", line 547, in send
    raise ConnectionError(err, request=request)
requests.exceptions.ConnectionError: ('Connection aborted.', RemoteDisconnected('Remote end closed connection without response'))
"
2023-09-03 10:27:41,288 (__init__.py:960 MainThread) ERROR - TeleBot: "Infinity polling exception: ('Connection aborted.', RemoteDisconnected('Remote end closed connection without response'))"
2023-09-03 10:27:41,289 (__init__.py:962 MainThread) ERROR - TeleBot: "Exception traceback:
Traceback (most recent call last):
  File "/home/venv/lib/python3.10/site-packages/urllib3/connectionpool.py", line 703, in urlopen
    httplib_response = self._make_request(
  File "/home/venv/lib/python3.10/site-packages/urllib3/connectionpool.py", line 449, in _make_request
    six.raise_from(e, None)
  File "<string>", line 3, in raise_from
  File "/home/venv/lib/python3.10/site-packages/urllib3/connectionpool.py", line 444, in _make_request
    httplib_response = conn.getresponse()
  File "/usr/local/lib/python3.10/http/client.py", line 1374, in getresponse
    response.begin()
  File "/usr/local/lib/python3.10/http/client.py", line 318, in begin
    version, status, reason = self._read_status()
  File "/usr/local/lib/python3.10/http/client.py", line 287, in _read_status
    raise RemoteDisconnected("Remote end closed connection without"
http.client.RemoteDisconnected: Remote end closed connection without response

During handling of the above exception, another exception occurred:

Traceback (most recent call last):
  File "/home/venv/lib/python3.10/site-packages/requests/adapters.py", line 489, in send
    resp = conn.urlopen(
  File "/home/venv/lib/python3.10/site-packages/urllib3/connectionpool.py", line 787, in urlopen
    retries = retries.increment(
  File "/home/venv/lib/python3.10/site-packages/urllib3/util/retry.py", line 550, in increment
    raise six.reraise(type(error), error, _stacktrace)
  File "/home/venv/lib/python3.10/site-packages/urllib3/packages/six.py", line 769, in reraise
    raise value.with_traceback(tb)
  File "/home/venv/lib/python3.10/site-packages/urllib3/connectionpool.py", line 703, in urlopen
    httplib_response = self._make_request(
  File "/home/venv/lib/python3.10/site-packages/urllib3/connectionpool.py", line 449, in _make_request
    six.raise_from(e, None)
  File "<string>", line 3, in raise_from
  File "/home/venv/lib/python3.10/site-packages/urllib3/connectionpool.py", line 444, in _make_request
    httplib_response = conn.getresponse()
  File "/usr/local/lib/python3.10/http/client.py", line 1374, in getresponse
    response.begin()
  File "/usr/local/lib/python3.10/http/client.py", line 318, in begin
    version, status, reason = self._read_status()
  File "/usr/local/lib/python3.10/http/client.py", line 287, in _read_status
    raise RemoteDisconnected("Remote end closed connection without"
urllib3.exceptions.ProtocolError: ('Connection aborted.', RemoteDisconnected('Remote end closed connection without response'))

During handling of the above exception, another exception occurred:

Traceback (most recent call last):
  File "/home/venv/lib/python3.10/site-packages/telebot/__init__.py", line 955, in infinity_polling
    self.polling(non_stop=True, timeout=timeout, long_polling_timeout=long_polling_timeout,
  File "/home/venv/lib/python3.10/site-packages/telebot/__init__.py", line 1043, in polling
    self.__threaded_polling(non_stop=non_stop, interval=interval, timeout=timeout, long_polling_timeout=long_polling_timeout,
  File "/home/venv/lib/python3.10/site-packages/telebot/__init__.py", line 1118, in __threaded_polling
    raise e
  File "/home/venv/lib/python3.10/site-packages/telebot/__init__.py", line 1073, in __threaded_polling
    polling_thread.raise_exceptions()
  File "/home/venv/lib/python3.10/site-packages/telebot/util.py", line 109, in raise_exceptions
    raise self.exception_info
  File "/home/venv/lib/python3.10/site-packages/telebot/util.py", line 91, in run
    task(*args, **kwargs)
  File "/home/venv/lib/python3.10/site-packages/telebot/__init__.py", line 649, in __retrieve_updates
    updates = self.get_updates(offset=(self.last_update_id + 1),
  File "/home/venv/lib/python3.10/site-packages/telebot/__init__.py", line 623, in get_updates
    json_updates = apihelper.get_updates(self.token, offset, limit, timeout, allowed_updates, long_polling_timeout)
  File "/home/venv/lib/python3.10/site-packages/telebot/apihelper.py", line 321, in get_updates
    return _make_request(token, method_url, params=payload)
  File "/home/venv/lib/python3.10/site-packages/telebot/apihelper.py", line 156, in _make_request
    result = _get_req_session().request(
  File "/home/venv/lib/python3.10/site-packages/requests/sessions.py", line 587, in request
    resp = self.send(prep, **send_kwargs)
  File "/home/venv/lib/python3.10/site-packages/requests/sessions.py", line 701, in send
    r = adapter.send(request, **kwargs)
  File "/home/venv/lib/python3.10/site-packages/requests/adapters.py", line 547, in send
    raise ConnectionError(err, request=request)
requests.exceptions.ConnectionError: ('Connection aborted.', RemoteDisconnected('Remote end closed connection without response'))
"
2023-09-03 16:05:37,106 (__init__.py:960 MainThread) ERROR - TeleBot: "Infinity polling exception: ('Connection aborted.', RemoteDisconnected('Remote end closed connection without response'))"
2023-09-03 16:05:37,107 (__init__.py:962 MainThread) ERROR - TeleBot: "Exception traceback:
Traceback (most recent call last):
  File "/home/venv/lib/python3.10/site-packages/urllib3/connectionpool.py", line 703, in urlopen
    httplib_response = self._make_request(
  File "/home/venv/lib/python3.10/site-packages/urllib3/connectionpool.py", line 449, in _make_request
    six.raise_from(e, None)
  File "<string>", line 3, in raise_from
  File "/home/venv/lib/python3.10/site-packages/urllib3/connectionpool.py", line 444, in _make_request
    httplib_response = conn.getresponse()
  File "/usr/local/lib/python3.10/http/client.py", line 1374, in getresponse
    response.begin()
  File "/usr/local/lib/python3.10/http/client.py", line 318, in begin
    version, status, reason = self._read_status()
  File "/usr/local/lib/python3.10/http/client.py", line 287, in _read_status
    raise RemoteDisconnected("Remote end closed connection without"
http.client.RemoteDisconnected: Remote end closed connection without response

During handling of the above exception, another exception occurred:

Traceback (most recent call last):
  File "/home/venv/lib/python3.10/site-packages/requests/adapters.py", line 489, in send
    resp = conn.urlopen(
  File "/home/venv/lib/python3.10/site-packages/urllib3/connectionpool.py", line 787, in urlopen
    retries = retries.increment(
  File "/home/venv/lib/python3.10/site-packages/urllib3/util/retry.py", line 550, in increment
    raise six.reraise(type(error), error, _stacktrace)
  File "/home/venv/lib/python3.10/site-packages/urllib3/packages/six.py", line 769, in reraise
    raise value.with_traceback(tb)
  File "/home/venv/lib/python3.10/site-packages/urllib3/connectionpool.py", line 703, in urlopen
    httplib_response = self._make_request(
  File "/home/venv/lib/python3.10/site-packages/urllib3/connectionpool.py", line 449, in _make_request
    six.raise_from(e, None)
  File "<string>", line 3, in raise_from
  File "/home/venv/lib/python3.10/site-packages/urllib3/connectionpool.py", line 444, in _make_request
    httplib_response = conn.getresponse()
  File "/usr/local/lib/python3.10/http/client.py", line 1374, in getresponse
    response.begin()
  File "/usr/local/lib/python3.10/http/client.py", line 318, in begin
    version, status, reason = self._read_status()
  File "/usr/local/lib/python3.10/http/client.py", line 287, in _read_status
    raise RemoteDisconnected("Remote end closed connection without"
urllib3.exceptions.ProtocolError: ('Connection aborted.', RemoteDisconnected('Remote end closed connection without response'))

During handling of the above exception, another exception occurred:

Traceback (most recent call last):
  File "/home/venv/lib/python3.10/site-packages/telebot/__init__.py", line 955, in infinity_polling
    self.polling(non_stop=True, timeout=timeout, long_polling_timeout=long_polling_timeout,
  File "/home/venv/lib/python3.10/site-packages/telebot/__init__.py", line 1043, in polling
    self.__threaded_polling(non_stop=non_stop, interval=interval, timeout=timeout, long_polling_timeout=long_polling_timeout,
  File "/home/venv/lib/python3.10/site-packages/telebot/__init__.py", line 1118, in __threaded_polling
    raise e
  File "/home/venv/lib/python3.10/site-packages/telebot/__init__.py", line 1073, in __threaded_polling
    polling_thread.raise_exceptions()
  File "/home/venv/lib/python3.10/site-packages/telebot/util.py", line 109, in raise_exceptions
    raise self.exception_info
  File "/home/venv/lib/python3.10/site-packages/telebot/util.py", line 91, in run
    task(*args, **kwargs)
  File "/home/venv/lib/python3.10/site-packages/telebot/__init__.py", line 649, in __retrieve_updates
    updates = self.get_updates(offset=(self.last_update_id + 1),
  File "/home/venv/lib/python3.10/site-packages/telebot/__init__.py", line 623, in get_updates
    json_updates = apihelper.get_updates(self.token, offset, limit, timeout, allowed_updates, long_polling_timeout)
  File "/home/venv/lib/python3.10/site-packages/telebot/apihelper.py", line 321, in get_updates
    return _make_request(token, method_url, params=payload)
  File "/home/venv/lib/python3.10/site-packages/telebot/apihelper.py", line 156, in _make_request
    result = _get_req_session().request(
  File "/home/venv/lib/python3.10/site-packages/requests/sessions.py", line 587, in request
    resp = self.send(prep, **send_kwargs)
  File "/home/venv/lib/python3.10/site-packages/requests/sessions.py", line 701, in send
    r = adapter.send(request, **kwargs)
  File "/home/venv/lib/python3.10/site-packages/requests/adapters.py", line 547, in send
    raise ConnectionError(err, request=request)
requests.exceptions.ConnectionError: ('Connection aborted.', RemoteDisconnected('Remote end closed connection without response'))
"
